model
name = cas
size = 45 31 45
scale = 0.05
origin = -y
material type = toon, lighting = smooth, deform = 1 1 
  colors = A:#AAA B:#555 C:#888 D:#90C E:#CF3 F:#6C0 G:#6F6
voxels
2(45B1350-)45B4-7(38A7-)9(A-)2A9(-A)993-45B3-8AD22-D3(8A5-8A24-)8A5-8A24C8A5-8A24-8A5-7A26-7A5-8A24-8A6-A-3A-A24-A-3A-A7-F-3A28-3A-F9-8(3A28-3A11-)3A28-3A10-5A26-5A53-7A24-7A7-3(A-)A24-3(A-)A7-E36-E273-45B3-4(8A24-8A5-)8A24C8A5-8A24-8A5-7A26-7A6-7A24-7A8-10(5A26-5A9-)5A26-5A8-7A24-7A8-5A26-5A8-7A24-7A363-45B3-4(8A24-8A5-)8A24C8A3(5-9A22-9A)6-8A22-8A11(7-7A24-7A)8-5A26-5A8-2A3-2A24-2A3-2A7-A5-A24-A5-A318-45B3-4(8A24-8A5-)8A3C18-3C8A5-4AD30-D4A5-4A32-4A6-3A32-3A7-8A22-8A11(7-7A24-7A)8-5A26-5A8-2A3-2A24-2A3-2A363-45B3-4(8A24-8A5-)8A3C18-3C8A3(5-4A-4A22-4A-4A)6-8A22-8A11(7-7A24-7A)8-5A26-5A8-2A3-2A24-2A3-2A7-A5-A24-A5-A318-45B3-4(8A24-8A5-)8A3C18-3C8A5-4A-3A24-3A-4A5-4A-2A26-2A-4A6-3A-3A24-3A-3A8-10(5A26-5A9-)5A26-5A8-7A24-7A8-5A26-5A8-7A24-7A363-45B3-4(8A24-8A5-)8A3C18-3C8A5-4A-3A24-3A-4A5-A2-A-A28-A-A2-A5-4A-3A24-3A-4A6-A-3A28-3A-A9-9(3A28-3A11-)3A28-3A10-5A26-5A53-7A24-7A7-3(A-)A24-3(A-)A13-F24-F279-45B3-AD36-D3(A5-A38-)A5-A10C18-10C2(A5-A2-A-A28-A-A2-)A8-A-A28-A-A11-3A28-3A950-45B3-4(A13-A10-A13-A5-)A11C2-A10-A2-11C3(A5-A13-A10-A13-)A19-13(A10-A33-)E10-E376-45B3-4(A38-A5-)A12C14-12C2(A5-A38-)A334-C10-C123-C10-C78-C10-C466-45B3-4(A38-A5-)A3C5-5C12-5C5-3C3(A5-A38-)A244-C10-C123-C10-C78-C10-C511-45B3-4(A14-10A14-A5-)A3C6-5C10A5C6-3C2(A5-A13-12A13-)A19-12A33-2(12A78-)C10-C123-C10-C78-C10-C217-A2-A39-3(A-A2-A-A37-)A-A2-A-A39-A2-A110-45B3-4(A13-A10-A13-A5-)A3C7-18C7-3CA5-A14-D8-D14-2(A5-A38-)A18-2A10-2A32-12A32-14A32-C10-C123-C10-C78-C10-C82-A2-A39-A-A2-A-A35-2(2(A-)A2-2(A-)A33-)2(A-)A2-2(A-)A32-2A2(-A)2-2(A-)2A31-6A2-6A31-2A2(-A)2-2(A-)2A31-2(A2-A-)A2-A31-A4-A2-A4-A36-A2-A41-G2-G20-45B3-A8-A3-AD10-D2(A3-A8-A5-A8-A3-A12-)A3-A8-A5-A8-A3-14A3-A8-A5-A3C5-A2-16C2-A5-3C2(A5-A8-A2-A14-A2-A8-)2(A14-A2-)A23-A2-16A2-A23-A3-14A3-A23-A2-16A2-A23-A3-C12AC3-A23-A2-C-12A-C2-A23-A-C2-12A2-C-A23-AC2-C12AC2-CA23-A2-C-12A-C2-A23-A2(-C)12A2(C-)A23-A2(C-)12A2(-C)A23-A-C2-12A2-C-A23-AC3-12A3-CA23-A3-14A3-A23-E3-14A3-E27-3(14A31-)14A195-45B3-3(A11-A14-A11-A5-)A11-A-12A-A11-A5-A3C8-A14CA8-3CA5-A11-AD12-D2(A11-A5-A11-A14-)A11-A17-A-12A-A30-14A30-16A31-12(12A33-)12A32-14A32-A10-A196-45B3-3(A11-A14-A11-A5-)A11-A-12A-A11-A5-A3C8-A14CA8-3C2(A5-A11-A14-A11-)A17-A14-A29-A-12A-A30-14A30-16A31-7(12A33-)12A32-3(14A31-)14A30-2(16A29-)3A10-3A29-2A12-2A149-45B3-3(A11-A14-A11-A5-)A11-A-12A-A11-A5-A3C8-A14CA8-3C3(A5-A11-A14-A11-)A17-A-12A-A30-14A30-16A31-12(12A33-)12A32-14A32-A10-A196-45B3-3(A10-2A14-2A10-A5-)A10-2A-12A-2A10-A5-A3C8-A14CA8-3C2(A5-A11-A14-A11-)A17-A14-A29-A-12A-A30-14A30-16A31-6(12A33-)12A32-3(14A31-)14A30-3(16A29-)3A10-3A2(29-2A12-2A)30-A12-A31-G12-G15-2(45B3-3(A38-A5-)A10-2A-12A-2A10-A5-A3C8-A14CA8-3C3(A5-A11-A14-A11-)A17-A-12A-A30-14A30-16A31-14(12A33-)A10-A196-)45B3-3(A10-2A14-2A10-A5-)A10-2A-12A-2A10-A5-A3C8-A14CA8-3C2(A5-A11-A14-A11-)A17-A14-A29-A-12A-A30-14A30-16A31-6(12A33-)12A32-3(14A31-)14A30-3(16A29-)3A10-3A2(29-2A12-2A)30-A12-A31-G12-G15-45B3-3(A11-A14-A11-A5-)A11-A-12A-A11-A5-A3C8-A14CA8-3C3(A5-A11-A14-A11-)A17-A-12A-A30-14A30-16A31-12(12A33-)12A32-14A32-A10-A196-45B3-3(A11-A14-A11-A5-)A11-A-12A-A11-A5-A3C8-A14CA8-3C2(A5-A11-A14-A11-)A17-A14-A29-A-12A-A30-14A30-16A31-7(12A33-)12A32-3(14A31-)14A30-2(16A29-)3A10-3A29-2A12-2A149-45B3-3(A11-A14-A11-A5-)A11-A-14A11-A5-A3C8-A14CA8-3CA5-A11-AD12-D2(A11-A5-A11-A14-)A11-A17-A-12A-A30-14A30-16A31-12(12A33-)12A32-14A32-A10-A196-45B3-A8-A3-AD10-D2(A3-A8-A5-A8-A3-A12-)A3-A8-A5-A8-A3-14A3-A8-A5-A3C5-A2-16C2-A5-3C2(A5-A8-A2-A14-A2-A8-)2(A14-A2-)A23-A2-16A2-A23-A3-14A3-A23-A2-16A2-A23-A3-C12AC3-A23-A2-C-12A-C2-A23-A-C2-12A2-C-A23-AC2-C12AC2-CA23-A2-C-12A-C2-A23-A2(-C)12A2(C-)A23-A2(C-)12A2(-C)A23-A-C2-12A2-C-A23-AC3-12A3-CA23-A3-14A3-A23-E3-14A3-E27-3(14A31-)14A195-45B3-3(A13-A10-A13-A5-)A13-12A13-A5-A3C7-18C7-3CA5-A14-D8-D14-2(A5-A38-)A18-2A10-2A32-12A32-14A32-C10-C123-C10-C78-C10-C82-A2-A39-A-A2-A-A35-2(2(A-)A2-2(A-)A33-)2(A-)A2-2(A-)A32-2A2(-A)2-2(A-)2A31-6A2-6A31-2A2(-A)2-2(A-)2A31-2(A2-A-)A2-A31-A4-A2-A4-A36-A2-A41-G2-G20-45B3-3(A14-4A2-4A14-A5-)A14-10A14-A5-A3C6-5C10A5C6-3C2(A5-A13-12A13-)A19-12A33-2(12A78-)C10-C123-C10-C78-C10-C217-A2-A39-3(A-A2-A-A37-)A-A2-A-A39-A2-A110-45B3-3(A17-A2-A17-A5-)A17-4A17-A5-A3C5-5C12-5C5-3C3(A5-A38-)A244-C10-C123-C10-C78-C10-C511-45B3-4(A38-A5-)A12C14-12C2(A5-A38-)A334-C10-C123-C10-C78-C10-C466-45B3-4(A13-A10-A13-A5-)A11C2-A10-A2-11C3(A5-A13-A10-A13-)A19-13(A10-A33-)E10-E376-45B3-AD36-D3(A5-A38-)A5-A10C18-10C2(A5-A2-A-A28-A-A2-)A8-A-A28-A-A11-3A28-3A950-45B3-4(8A24-8A5-)8A3C18-3C8A5-4A-3A24-3A-4A5-A2-A-A28-A-A2-A5-4A-3A24-3A-4A6-A-3A28-3A-A9-9(3A28-3A11-)3A28-3A10-5A26-5A53-7A24-7A7-3(A-)A24-3(A-)A13-F24-F279-45B3-4(8A24-8A5-)8A3C18-3C8A5-4A-3A24-3A-4A5-4A-2A26-2A-4A6-3A-3A24-3A-3A8-10(5A26-5A9-)5A26-5A8-7A24-7A8-5A26-5A8-7A24-7A363-45B3-4(8A24-8A5-)8A3C18-3C8A3(5-4A-4A22-4A-4A)6-8A22-8A11(7-7A24-7A)8-5A26-5A8-2A3-2A24-2A3-2A7-A5-A24-A5-A318-45B3-4(8A24-8A5-)8A3C18-3C8A5-4AD30-D4A5-4A32-4A6-3A32-3A7-8A22-8A11(7-7A24-7A)8-5A26-5A8-2A3-2A24-2A3-2A363-45B3-4(8A24-8A5-)8A24C8A3(5-9A22-9A)6-8A22-8A11(7-7A24-7A)8-5A26-5A8-2A3-2A24-2A3-2A7-A5-A24-A5-A318-45B3-4(8A24-8A5-)8A24C8A5-8A24-8A5-7A26-7A6-7A24-7A8-10(5A26-5A9-)5A26-5A8-7A24-7A8-5A26-5A8-7A24-7A363-45B3-8AD22-D3(8A5-8A24-)8A5-8A24C8A5-8A24-8A5-7A26-7A5-8A24-8A6-A-3A-A24-A-3A-A7-F-3A28-3A-F9-8(3A28-3A11-)3A28-3A10-5A26-5A53-7A24-7A7-3(A-)A24-3(A-)A7-E36-E273-45B2(4-17A)2(7-17A4-17A)4(7-38A)7-9(A-)2A9(-A)993-45B18-3(A-A4-A-A35-)A-6A-A35-E-A-2A-A-E1142-2(45B1350-)
