model
name = pieta
size = 104 126 70
scale = 0.05
origin = -y
material type = toon, lighting = smooth, deform = 1 1 
  colors = A:#F0F2F6 B:#EEF0F4 C:#F1F3F7 D:#EAECF0 E:#ECEEF2 F:#EDEFF4 G:#E2E4E8 H:#E6E8EC I:#DADCE0 J:#DEE0E4 K:#D6D8DC L:#E4E6EA M:#E0E2E6 N:#E8EAEE O:#D2D4D8 P:#DCDEE2 Q:#C4C6C9 R:#CACCD0 S:#E9ECEE T:#CED0D4 U:#BCBEC1 V:#BABCBE W:#C8CACD X:#D8DADE Y:#F2F4F8 Z:#C2C4C8 Aa:#C6C8CC Ab:#E1E3E7 Ac:#BEC0C4 Ad:#949698 Ae:#B6B8BA Af:#B4B6B9 Ag:#B8BABD Ah:#989A9C Ai:#9EA0A2 Aj:#D0D2D5 Ak:#D4D6DA Al:#CCCED1 Am:#C0C2C5 An:#D7DAE0 Ao:#DDDEE4 Ap:#ACAEB1 Aq:#96989A Ar:#AEB0B2 As:#BABDC0 At:#909294 Au:#E5E6EC Av:#9A9C9E Aw:#A6A8AA Ax:#CED1D8 Ay:#929496 Az:#D5D6DC Ba:#A4A6A9 Bb:#CCCED4 Bc:#9C9EA1 Bd:#8E9092 Be:#C5C8CA Bf:#D1D4D6 Bg:#B0B2B5 Bh:#B2B4B6 Bi:#CDD0D2 Bj:#86888A Bk:#8C8E90 Bl:#7E8082 Bm:#A8AAAD Bn:#8A8C8E Bo:#858688 Bp:#A0A2A5 Bq:#B6B9BC Br:#595A5C Bs:#D9DAE0 Bt:#828486 Bu:#C1C4C6 Bv:#9B9C9F Bw:#5C5D5E Bx:#4E5051 By:#4E4E50 Bz:#515254 Ca:#9FA1A4 Cb:#565859 Cc:#4A4A4C Cd:#5E6061 Ce:#D9DCDE Cf:#D1D2D8 Cg:#555658 Ch:#7A7C7E Ci:#DFE3E7 Cj:#626465 Ck:#505152 Cl:#666869 Cm:#D2D6DC Cn:#898A8C Co:#CACDD4 Cp:#B2B5B8 Cq:#656668 Cr:#ECF0F2 Cs:#A2A4A6 Ct:#AAACAE Cu:#7D7E80 Cv:#BDC0C2 Cw:#5A5C5D Cx:#6E7071 Cy:#98999B Cz:#76787A Da:#AEB1B4 Db:#545556 Dc:#C9CCCE Dd:#58595A De:#4C4D4E Df:#5D5E60 Dg:#3E3E40 Dh:#616264 Di:#606162 Dj:#696A6C Dk:#818284 Dl:#717274 Dm:#3A3A3C Dn:#464648 Do:#757678 Dp:#A3A4A7 Dq:#727475 Dr:#232324 Ds:#48494A Dt:#525455 Du:#68696A Dv:#E9EAF0 Dw:#AAACAF Dx:#646566 Dy:#7C7D7E Dz:#AAADB0 Ea:#6C6D6E Eb:#6D6E70 Ec:#C4C7CC Ed:#A6A9AC Ee:#78797A Ef:#282929 Eg:#444546 Eh:#2F3030 Ei:#424244 Ej:#C8CAD0 Ek:#6A6C6D El:#A7A9AB Em:#4A4C4D En:#D5D8DA Eo:#1D1D1D Ep:#707172 Eq:#747576 Er:#797A7C Es:#3C3D3E Et:#2C2D2E Eu:#C6C9D0 Ev:#212121 Ew:#323234 Ex:#252526 Ey:#8E9194 Ez:#3E4041 Fa:#C1C2C8 Fb:#191919 Fc:#363638 Fd:#272728 Fe:#2B2B2C Ff:#303132 Fg:#2E2E30 Fh:#38393A Fi:#171718 Fj:#3A3C3C Fk:#343536 Fl:#808182 Fm:#404142 Fn:#E5E8EA Fo:#848586 Fp:#88898A Fq:#C2C5CC Fr:#1B1B1C Fs:#151515 Ft:#929598 Fu:#424445 Fv:#B1B3B8 Fw:#1F1F20 Fx:#8C8C8E Fy:#DDE0E2 Fz:#8A8D90 Ga:#131314 Gb:#2A2A2C Gc:#A2A5A8 Gd:#CED4D8 Ge:#9A9DA0 Gf:#464849 Gg:#96999C Gh:#7E8184 Gi:#262628 Gj:#F0F4F6 Gk:#BCBFC4 Gl:#909092 Gm:#E1E4E6 Gn:#DAE0E4 Go:#A9AAB0 Gp:#B9BAC0 Gq:#161618 Gr:#D6DCE1 Gs:#A4A6AB Gt:#1E1E20 Gu:#222224 Gv:#363838 Gw:#323434 Gx:#1A1A1C Gy:#9EA1A4 Gz:#D6DBDD Ha:#B8BAC0 Hb:#ACAEB4 Hc:#86898C Hd:#121214 He:#111 Hf:#AFB2B5 Hg:#C7CBCD Hh:#D2D9DD Hi:#7A7C80 Hj:#828488 Hk:#6E7174 Hl:#C6CCD2 Hm:#B4B6BC Hn:#949496 Ho:#0D0D0D Hp:#E2E8EA Hq:#727478 Hr:#BEC2C7 Hs:#F4F6FA Ht:#DAE0E2 Hu:#DEE4E6 Hv:#E7EDF0 Hw:#76787C Hx:#E6EBEE Hy:#CED4D6 Hz:#EDF4F6 Ia:#CAD0D3
voxels
3431-2(A103-)2(C103-)C9260-B3C8A3C11A21C11A9B2A6B2FBFE2F4H4Au2LG3PBsIPBs4-C102-2(Y103-)Y102-2(C103-)A2(103-B)103-F102-S103-L103-G102-K104-J2(103-H)102-2(E103-)2(B103-)A103-B2(103-A)6(103-C)103-A104-B103-B104-E104-2E104-4H2(G104-)Ab2(104-2Fn)104-AuFn104-L104-K104-En6-AwCt2DwBg93-2K2-AgAr5-2CaAr92-2U10-2U2Z4Q104-Q2(2Aa104-)Aa2(104-2Aa)104-AaQ104-2Z104-2Bu104-U2(104-2U)104-2As104-As104-2As104-V104-2Cp104-Cp104-Bg104-Ap104-Ae103-Ae104-Ag103-Ag104-V103-Ag102-Bq103-Af102-Ap2(103-Da)102-Ai104-Da2AfAt2BdBk104-Av103-AeCu103-Ge9-FjEwDr2FeEh88-Ge6-2FfFg6-Es87-2Ay3-CgDg10-Dn87-At2ClDx12-Dn104-Dg103-Dg104-Dm104-Et103-Fg934-FbDr101-2Fb100-FcFb101-2Fc101-DmFf101-Bz103-Bz102-Dj103-Ek102-Ek103-Cx103-Do102-Ch2(103-Bl)102-Cu103-Dy2(103-Cu)102-Bt103-Bt102-Bj102-Bn103-Bk3(102-Bd)21-4C8A5C2(AC)A3CA19C9A18B3F2EF4D4L2GLGAb2M3Bs2(IBs)4-C103-C102-2(Y103-)2(C103-)2(A103-)B102-B2(103-S)102-G103-Ab103-Ao2(103-S)103-F5(103-B)3(103-A)103-C103-F103-B103-A3(103-B)104-B104-F104-2DH104-2H2G104-M104-J104-L104-3L104-Fn104-L104-Aj8-Ct95-En4-Bh2Ar-Dw95-2WBhV5-ElDp104-AsAcAmAcZ6Q104-2QAa104-2Q104-AaQ104-Aa104-2Aa104-2Be104-ZBu104-BuAm104-CvU2(104-2U)104-As104-2As104-V18-EoEf84-AgCp17-EoEf85-Cp17-Fd86-Bh104-Bg104-Ap104-Cp104-Ag103-Ag104-2(V103-)Ag103-Bq102-Ae103-Bh102-2(Da103-)Dz103-3AfCy2BdBkFz104-EyCu103-Cu5-Cq2De2Fj2FkDm90-Bt4-CjBw4Fj3-FkEs88-2BdBn-BwBxByFj8-Es88-BtDj2Df11-Ds104-Dn103-Ez104-Ez103-Dm104-Gw2(103-Fg)623-Fw102-FbEv100-2Fb100-FjFdFb100-EsFj102-Es102-Br102-Dh103-Ek102-2(Dj103-)Ek102-Ep103-Eq103-Ch103-Bl102-Bl103-Cu2(103-Dy)102-Fl103-Fl102-At103-Bd102-Fx102-Bk103-2(Bd102-)Bd22-3C8A30C9A20B3F4D2(NH)7GAoPIPAnXAnAoCi2J4-C2(103-Y)2(103-C)102-4(A103-)B103-S102-S103-Ab102-MAb103-G103-N103-E2(103-Cr)2(103-B)103-A103-B4(103-A)103-C2(103-A)3(103-B)104-B104-D104-3HFn104-3G104-J103-J2(104-2L)104-G104-L104-Aj6-ArAfBg95-Al3-BgBh3-Ah95-2WBh5-Ah104-2ZU2Am3Z2Be4Q104-2QZ2(104-Q)Be104-2Be2(104-Be)2Q104-2Bu104-2Am104-Cv2(U104-)2U104-As20-FkFm82-2As18-Fg2Fk83-As17-Eo2-Gb83-AgCp15-2Fb2-Fb84-Cp15-FrFb-Fw85-Bh15-GtEvEf86-Bh16-2Ef86-Bh104-Af2(104-Ag)2(103-V)104-Ag103-Bq2(102-Ae)2(103-Af)102-Bh104-UAsDpBcAvAyFzBnBt104-CzEeEkCl2CqBz2DeDn2FkDg91-BtDkDj2Cl8-DmFj89-BtDk2Dj11-Dm90-Cz13-Bx103-By103-Dn104-Dn103-Ei103-Dm104-Fc2(103-Ew)519-Gt101-2Gx100-EhGxFb100-EhEt101-Cj102-Dl103-Cz102-Ch103-Ee102-Fl103-Do103-Bt102-Bt103-Cz103-Bl103-Bo103-Bn102-Hc103-Fo2(103-Fp)102-Bt103-Bn102-At103-Bd102-Ay102-Aq102-Ad103-Hn102-At22-2AC8A26C3AC5ABA15B2AB4F3EDHNSLG2L3G3AbGAnAzI4K2Ci2L5-C103-C102-4(C103-)A102-2(A103-)B103-E103-D103-Au103-H102-Ab104-Au103-E2(103-Cr)4(103-B)102-A104-3(A103-)C103-A4(103-B)104-E104-D104-2HLG104-3G104-J103-J104-2L104-L104-G104-H104-T4-2Ar2Af96-RAa2Bg4-Ah103-Av104-AmZ2QBe3Aa3Be5Q2(104-2Z)104-2Be2(104-Be)2Q2(104-2Am)104-2U104-UAs104-U20-EfFh82-U19-FiEoEgEt81-2As18-Fi2-Ev82-As17-Fi3-Fs82-As16-Fs4-Fi82-BqAf14-Ga4-Fi84-Af14-Ga4-Eo84-Af14-Gt3-Ex85-Af14-GtGu2-Et85-Bh15-EfFg87-Cp104-Ae104-V103-V104-U103-V103-Ag103-Ae102-Ag103-As102-Gp103-Cp104-Q2CtBaAvBkBn2Er2EpCjDfBr2CbDtBrDn104-Ds2Cc104-Dn104-Bx104-Cg104-Dt103-Em103-Ei104-2(Ez103-)Dm622-EoGt100-Fr2Eo99-Eh2Gx100-FkEh102-Ds102-Du102-Eq103-Cz103-Ch103-Dk102-Bt103-Bo103-Bt102-Bt103-Bj2(103-Bk)103-Bd102-Ey103-Bk2(103-Fp)102-Bd103-Ay102-Aq103-3(Aq102-)Ad102-Aq102-Ad24-AC8A24C8ABA21B6EDN2AuHAb4M2Ab2M2AbCm2OCm3KAuNDN5-A3(103-C)102-2(C103-)4(A103-)F103-E102-L103-H103-L103-D104-E102-7(B103-)A103-B103-A103-C103-A3(103-B)104-E104-N104-S104-NL2G104-3G104-Fy103-G2(104-Ab)2(G104-)W5-Bg98-W2QBhDa-Am104-Cy103-Ap104-AmZ3WAa2W3AaBe4Q104-Q2(2Z104-)2Q104-ZAm104-QBu104-2Am104-AcU104-2U21-FkDg81-2As19-FdEt2Fk81-As19-Ex2-2Fw80-UAs17-Fr4-Fs81-U16-2Ga3-Fs82-As16-Ga4-Fi82-U15-Ga5-Fi82-Ag15-Ga4-Fi83-2Ae13-Ga5-Dr84-Bq13-Ga4-Dr85-Bq13-Hd4-Et85-Af13-HdHe2-Ew86-Ae14-EvEtFf87-Ae104-V104-As103-Cv104-U2(103-V)102-U102-BeAm102-Q103-Am104-Ae2ApAh2Ay2ErCzEpHkDuCl2CbDfBr104-2Cd104-DtBz104-Dn104-Cg104-Db104-Dt104-Dn103-Dn725-3Ev100-EoFw100-EtFe101-Eh102-Cg103-Cd102-2(Cx103-)Do103-Ch102-2(Bt103-)Bo103-Bo102-2(Bo103-)Bn103-Bk102-Ey103-Bd2(103-Bk)102-2(Bd103-)Ft102-Aq102-Cy103-3(Aq102-)Ad102-Ay24-2A4CACA25C8A23B4D3SHL2Au2(MJ)IJAb2J2M2AzOKIAnPN3E6-A103-A102-4(C103-)C102-2(C103-)A103-B103-E103-N103-Dv103-S103-D103-F10(103-B)3(103-A)103-B103-F104-D104-H104-S104-4G104-GAb104-Ce104-M2(104-G)104-P104-Z2-Ac2BqAe98-ZQ4-Dp103-Aw104-Ap104-WBeW2RDc3W3AaBe2QBe104-3Q104-QZ104-2ZAm104-AmAc104-AcCv104-V2Ag104-Bq21-EwFkFh80-BqAg19-Fk2-2Fd80-AgV17-Fd4-Eo81-V17-Dr4-Fb81-V16-Eo5-Gq81-As15-Fs6-Fs81-U15-Ga5-Fs82-Ae15-Ga4-Fi83-U14-Fs4-Fi84-Ag13-Fs5-Ev84-2Ag12-Fs5-Ev85-Bq12-Hd5-Et85-Bq12-2Hd3-Eh86-Ag13-Ga3-Fc86-Ag13-2GwGvEm87-V13-2FmFuEm87-As104-Cv103-U104-V103-V102-V103-Am102-AaAc102-ZVAgBhBa104-Bc2AtBtBlChEq2CxDj2Ea104-2Dj104-DdBw104-Dt104-Dd104-Dt103-Ck104-Cc104-Fu103-Fu415-Eo101-3Ev99-2Fw100-GbEfDr101-Ew102-Bz103-Cg103-Bw102-2(Cx103-)Cz2(103-Bl)102-Bj103-Bo102-2(Bo103-)Bj102-Fz103-Bk2(103-Ay)102-Ft103-Bk2(103-Ey)102-Ay103-Ad102-Av103-Cy2(102-Aq)102-Ad102-Ay25-A26CA4C5A15BA10BFSN2S2HAu4L4M2I4P2AoPIJAbMHD3F6-2(A103-)C102-Y4(103-C)2(103-A)103-B103-F103-D2(103-S)103-D7(103-B)103-Ci2(103-E)103-B2(103-A)2(103-B)103-2(E104-)H103-DN104-2G2Ab104-AbJ104-I103-M104-Ab104-G104-I4-V99-2Z2Ac-As104-Aw103-Aw104-V104-3W2TAl4R3Aa4Be2(104-2Q)Z104-3Z104-2CvU104-VAe104-2Ae20-GwGvFhFjEf79-2Af18-EhEw3-2Fe79-Ag18-Ef5-Fd79-2V16-Fd6-Eo80-V16-Eo5-Fw81-V15-Ev6-Fr81-Ac15-Ga5-Fs82-Cv14-Fs5-Et83-V14-Gq4-Et84-U14-Fs4-Dr84-U13-Fs5-Ev84-U13-Fb5-Cc84-VU12-He5-Dg85-V12-Eo5-De85-V12-Ff5-Fc85-V11-2Ew4-2De85-Ac11-2Dg4-By86-Ac11-2DsBxCcDeByBx86-Ac12-Bx2DeByEm87-U14-ByEmCc86-V103-2V2(102-2Ag)2Aw100-2AgAp3Ba3Bk2CnBlDq93-4BaAd2Fx2BnCu2Dq104-EqDq104-DuDh104-Bw104-Dt104-Bw104-Bz103-Bz104-Gf103-Eg104-Fu103-Eg206-2Eo101-FwEo100-ExEv100-2Fd102-Dt102-Eq103-Dl103-Eb102-2(Dl103-)Bt103-Bj102-Bd2(103-Bj)102-2(At103-)Bd102-Ay103-Ay102-4(Ah103-)Aq103-Ey102-2(Cy103-)Av102-Bv102-Av103-Aq102-Ah102-Ad102-Ay25-2A20C15A12B6A4B5FN3H7G4M3KXBsPIL2G2HNHF3B7-A103-A102-7(C103-)2(A103-)D103-D102-2D2(103-D)103-Cr4(103-B)102-Cr2(103-B)104-R2(103-G)103-A3(103-B)103-F103-D104-H104-NL104-2GAb2(J104-)I104-P2(104-X)104-QAcAmVU104-Ct103-Ct104-Cv103-Ap104-8T3RW6Be104-2Q104-2AaZ2(104-2Z)Cv23-EtFh79-Ac2Ag20-2ExDm2EhEf78-2AeAf17-2Et4-DrFd79-Af17-Eh6-Fd79-Ae16-EtEf6-Eo79-VAs15-Gb6-Ho81-As15-Ex6-Dr81-U14-Fw6-Gb82-U14-Fr5-Fe83-Cv14-Fi5-Fe83-Am13-Gq5-Fe84-Am13-Gq5-By84-Cv12-Gq6-Dd84-U12-Fd6-Dd84-U12-Fr6-CbDe83-Ac11-EmDm7-Em83-AcV10-EsFe7-Em84-Ac9-2Dg8-By84-Ac9-EiEg7-DbBr84-Bu8-By2Cg7-Cg85-AcUBg5-DhCqCgDtCb5-ByDe85-2U2AdAt-EqCuDlDjDuDhCdCkBy3-Ez86-Ae2ApAiCa2BoCuEq2DuEa2(CkBy)Dn2Ez86-ArCsBpCaEy2CnBoErCzDoDhCbCkDbDs2Ez86-Ar2CsAiEy2CnBoCuChEeClBwCbBy91-CsAiBk3Bn2ChEa3Cl101-2EaCl102-2Cx104-Cx104-Du104-Eq104-Cd104-Cw104-Db103-Bx104-Em103-Eg104-Fu103-Es102-EoEs100-2Eo100-Fe2Ev100-DbFd101-Ea103-Ep2(103-Er)102-Dk103-Bt103-Bj102-Cn103-Fx103-Bd102-2(At103-)At102-At103-At102-Ay103-Ad4(103-Ah)102-2(Aq103-)Cy103-Cy102-Bv103-Av102-Av103-Av102-Ah101-2Ay101-Ay27-2A19C11A21BAB3F5EH3LM2JM3G4MAzKAzAn2BsI3ND2F5B7-B8(103-C)103-A2(103-F)2(103-B)103-D5(103-A)102-A2(103-E)103-D104-I102-G103-Cr103-B103-E103-Cr103-E103-F104-D104-G104-2L104-GAoJ2(I104-)K103-P104-Ak104-AjQAcEl2(Ae104-)Ct103-Ac103-Bu104-Ac104-2T2Aj2T2BiDcWRW2QBe2Aa104-2AaW104-2Aa104-QZQ24-FfEiFuGv76-2ZAc21-2Fe2-EwFcEw76-AcUV19-Ex5-2Fg77-3Ag16-Ef7-Eh79-Ae16-Et6-Ho80-Ae15-Ef7-Ho80-Ag15-Ef6-Ev81-Ac15-Dr6-Ev81-Ac15-Fw5-Ef82-Q14-Fr6-Fe82-AaQ13-Fi5-Et84-Am13-Gq5-Dm84-Z12-Fi6-Dx84-Z12-Gq6-DdCq83-Z11-Dm8-Df83-Q10-DmDn8-CqDt82-Z10-Bz10-Em82-ZAm8-2Cd10-By83-Am6-2EkCd11-Cw83-AcV3-GlDo2CjCk11-Cw84-VDaApAvFoBn2Ck11-Cg87-ArAd2BnDo12-Bx89-Bd13-Dn104-Dm103-Dn100-By2DsDn99-Db2ByDe100-Dj2Br101-2Cx103-Di104-Dj104-Cj103-Cd104-Cw104-Br103-By104-2(Ds103-)Ei102-FrDr101-2Fr99-FfEhFe100-CwDg102-Cw103-Dj2(103-Dq)102-Dy103-Bo103-Bt102-Bj103-Cn102-Bn103-At102-2(At103-)At102-At103-Ay103-At103-Ad102-3(Ah103-)2(Cy103-)2(Gg103-)Ah102-Bv103-Bv102-Av103-Av101-FtAq101-Ay102-Ay28-CA16C10A23BFBF2E5DEAu3LJ2PAo7MAnKAnAoPAoAb3DEF3B3A8-YC102-2C102-2Y102-3(C103-)A3(103-C)2(103-A)103-B2(103-Aj)3(103-A)102-3(A103-)B103-N2(103-I)103-M103-N103-D4(103-E)104-H103-G104-3L104-Ao2IO104-Bi103-K104-O104-R2Am2Dw104-Bg2(103-U)103-Z104-Bu103-Bu104-BfAj2OAk2T2BiW2AaQ2ZQWAa104-WR104-3W24-DmFhDgDnGfDs74-WAa23-FgFf3-EzDmDg73-AaQBu21-Fg6-Dg75-2AmAc19-Ef6-He77-3V16-Dr7-He79-Ag16-Dr6-He80-2Ag15-Ex6-Dr81-Am15-Ex5-Ex82-Am14-Dr6-Fe82-Am14-Fr6-Ef82-Am14-Eo6-Cb82-R13-Eo7-Cb82-Q13-Dr6-ByDq82-W12-Eg8-Cq82-AaW10-EgBx8-EbGv82-W9-CqDe10-Fm2De80-W8-BlBr12-DeEm80-Q7-BjCxBz12-EmCw80-2Am4-FtAyCxCw13-Cw82-2CvAp2AiBcGl15-Df84-3Ba16-Cw104-Bw104-Bz103-Cc104-Cc103-Ds103-Fm102-CkFm101-Cg102-2Cw102-DiBw2(103-Cb)104-Cd103-Br104-Bz103-Bz104-Ds103-Ei102-Fm102-Fr100-FkGwEf100-Dh103-Cw103-Cj103-Ee102-Bk103-Cn103-Bo102-2(Ad103-)Bk102-Bk103-Bk102-At103-At102-2(Ad103-)At103-Ay102-Ai2(103-Av)2(103-Ah)104-2(Ge103-)Gg102-Cy103-Ah103-3(Av102-)Ay2(102-Ad)101-2Ca29-ACA6CA2C2A2C11A14B4A4B2(FE)5D2SDAu3LP2IPMAoPJ3M3P2CiGAb3EF4B3A10-Y2(103-C)102-C103-A103-C2(103-B)103-C2(103-A)103-F103-D102-H104-E2(103-A)102-4(A103-)B103-D102-D104-G103-O103-G3(103-E)103-D103-E103-S104-H104-2AuP104-CeX2Q104-K103-Be103-2BeBuZVBh104-Ct103-Ac103-U2(103-Bu)103-Q104-Be103-XBf2KEn2O2TAl3AaQ2ZQW104-2WR25-DeCcEzCk3De72-2R24-Cc5-DeBx72-R2W22-Ew6-De74-WAa21-Et6-Ef75-2ZAm19-Ev6-Ex77-CvUV17-Dr5-DgEw79-AsU15-Dr6-Gb81-Ag15-Dr6-Cc81-V15-Dr6-Em81-Am15-Ev6-Dn81-2Am13-Ef7-Eg82-U13-Gb7-Cb82-R12-By8-Eb82-W11-2Fm8-Ee7-2Cc73-W10-2Bz9-DoCgGvCcBz3ByCc74-2Aa8-DbBz12-ByDe4By76-2W6-2Dy15-2ByBz77-WBuCvAwCsCtAtBlDy16-DtCb79-CvAeBgBhAhBnBj17-Cq81-2Bh2Ah18-Cq104-Cl103-Bw104-Cw103-Br104-Cc103-Ds104-Ei2(103-Ez)101-EzDg102-Ds103-Bw103-Cc103-Cb103-Dn104-Dn2(103-Bz)104-Ck102-Fm101-DrFr100-CkGwDr100-Ek103-Dh103-Dy102-Bo103-Fx103-Bd102-Ad103-Cy103-Ah102-Bv103-Bc102-Bp103-Cs102-Dp103-Ba103-Ad103-Ba102-3(Gc103-)Av103-Av104-Bc103-Cs2(103-Ge)2(103-Ah)102-Ah103-3(Av102-)Ay102-Ad101-2Aq101-Ca31-2CAB3ABAC12AB3A12B2A3BA2(BF)4DS6NDL3GI2XBs3IJ3MJMCiLH2N2F2B7A11-2(C103-)A102-2(C103-)6(A103-)A102-BfJ102-H104-B102-6(A103-)B103-Au102-G103-J104-K103-L2(103-E)102-E103-D103-E2(104-H)104-AuPX104-XZAm104-K104-U2ZQ104-Ct104-Ac102-Q103-Ec104-R103-Bi103-Q103-P104-BsX3K2O2TAl3AaEcAaQEcW27-Bz2Db3Cb71-2R25-De5-2Dt71-3T22-2De6-Bx73-2AlR20-2Cc6-Ds75-2R19-FfFk6-Ei76-AaZ19-Fk6-Dm77-QAmU17-Fd6-Es79-2U16-Eh6-Eg80-U15-Ei7-De80-BuV13-2Ei7-Bx81-Ac12-DfDeCb7-Cd81-2Am10-Ek2Cb8-Cz82-U8-AiCuCqClCd8-Dh9-By72-2Bq2AeBh2Ar2Ba2Bt2Cx9-2Cz5-BrCb2CcBx71-AeBqAeVAgBgArAw2BtBlCx11-FlCbBz2CgBzCg2-De72-U2AcAgAfCpAf2AdBdCd20-Dd74-AgAfCp2AfBaAd2Bd20-Dd77-AeAg2Cs2Bp20-Di103-Cj103-Cq2(103-Cl)103-Du104-Cd104-Cb104-De103-Ds103-Fu104-Ez103-Dg2(102-Fm)102-2(Cc103-)Ds103-Gf104-Dn103-Dn104-Ck102-Fm100-FfGbFb100-DgEw101-Dg102-Cx103-Er2(103-Bt)102-Bk103-Gl103-Ad102-Cy103-Ah102-2(Ai103-)Bp102-Cs103-Dp103-Gc103-Ba102-Ba103-Gc2(103-Ba)104-Ba103-Aw103-Ba103-Gc2(103-Bc)2(103-Ah)102-Av103-2(Av102-)Aq102-Aq101-2Cy101-Cy102-Bv33-A2(BF)B7AB3A2BAB3A18B2(ED)S3NH2Au4HSGJAbMI3An3I2CiAb2GLAuN2DE4B7A12-A103-C103-B102-2(C103-)A103-C5(103-A)103-B102-B104-A102-4(A103-)2(B103-)F102-2(Au103-)M104-K103-J103-Au102-2(H103-)Dv103-D104-N103-L104-HIBsX2(104-QZAa)104-Q104-Ae2(103-Ac)2(103-O)103-Ce104-P103-P45-2CwBrCb55-I2Ce3KAj2TBiW2AaWAa2WAl25-DhCw4-CwCbBw70-AlAj23-2Cl7-Br71-AjBfT20-ClDd8-Cb73-AjT19-BrBy8-Bx74-2T18-ByDe8-Dm75-T2Aa17-DnFc7-Dm77-AaBe16-2Dg7-Ez78-BeQ15-DhBw7-Ei79-QAa12-3Dh8-De80-Aa10-CnErCxEk9-Cd80-AaAc6-BpCyAq2BtBl10-Ep81-AgV-AfAe2BpBmAvBdAyAt11-CzCh7-Br2Bx71-2AgAeAr2BmArCyAy14-EqDkEe-2Du3Br-DfCg94-2DjDuCgDd5-Bx2(103-Dd)103-Bw102-Dh103-Dx3(103-Cl)104-Cj103-Cj104-Cb104-Ds103-Ds104-Ei2(103-Dg)103-Fm102-Es102-Gf103-Cc103-Ds103-Gf103-Eg104-Ds102-Fc100-2EtFb99-2Ff102-Dg102-Du2(103-Dq)102-Bk103-Fo103-Bk102-At2(103-Ad)102-Ah103-Bc102-Ai103-Aw103-Cs2(103-Dp)6(103-Ba)103-Aw103-Ba103-Gc103-Ai103-Bc103-Av103-Ah102-Gg103-2(Gg102-)Bd102-Ad101-2Ah100-2Ah101-El35-2FEFE2BAB3A8B3A14B3FEDN2S2(HAu)L2G2LGLHJI2AoI2BsI2JMAuLAu2H2NDvE2F4B4AC2A13-2(F103-)B102-3(A103-)C5(103-A)102-B7(103-A)103-F102-E103-H103-Ab103-I103-R104-Ab102-2(Au103-)N2(103-D)103-Au104-G104-2Ce2XW2(104-Q)2R104-R104-Ag103-As103-Ac2(103-O)103-K103-P104-J43-ClCj2DhCd2Cw54-I2Ce2X2En2TBiRAaW3RAlBi24-Dj7-BwCj70-TAj21-2Dj9-Du71-2BfO17-2DlDj10-Cb73-2O15-BlDqDjDu10-Cl74-2T14-DqDjDuDe10-Bx75-AjR13-CzDjDtCgCb9-Gf76-2W12-EeCq2DfBr9-By77-WAaW9-BtDo2DlDiCg9-Di79-2W6-2CyBjBl2Cn11-Dl80-Bi4-DpCs2AiBkCn13-Ee80-2UAgAr2ApBmBp16-EeBl6-2DfBrDf70-Ag2Ar21-BlDkDl2DxCx2Df2-2BwBr95-Ep8-Ck103-Bx2(103-Dd)103-Bw103-Cd103-Dx103-Cq2(103-Cl)103-Di104-Br103-Cw104-Bx104-Dn103-Ei2(103-Es)103-Dm103-2(Es102-)Cc103-Gf2(103-Cc)103-Ff99-EhFg2Fb99-2Ff101-Dk103-Ea103-Cz102-Aq103-Bn103-Bk102-Cy103-El103-Aw102-Ed103-Dz103-Bh102-Bh103-Aw103-Dz103-Ap103-Bm2(103-Ap)103-Da103-Ap2(103-Ar)103-Dz103-Ct2(103-Ba)103-Ge103-Ah2(103-Ad)102-Gg103-2(Gg102-)Bd101-AhCn100-2Ah101-Bp102-Ed35-E3DS15B3A12B2F3DEN3HL3GAb2M2GCiAbLIKBsAnBs2IJG2L2NDDvD2EF4B7A3C14-Cr2(103-B)102-3(A103-)2(C103-)3(A103-)A102-6(A103-)B102-B2(103-F)103-H103-Ab2(103-I)103-G103-L2(103-H)2(103-D)103-N104-Ao104-2Ce2REc104-2W104-2R104-Q103-V102-U103-Cv104-R2(103-K)103-P46-2Cq56-J3PX38-EbDuDx2-3Di58-2XO3TR2W2RTAl23-CzEq8-2Eb69-3T19-ChEe11-Du71-2Ak16-BlCu13-Dj72-2AkO13-2Bl14-Cl74-2O11-DkFlCu14-Eq75-TR9-2BoBnCz14-Eb76-2R6-BaAyBnBkCzFl14-Dq77-2WQ3-AwCa2AiBdBn15-Ch79-Aa2BiBgCpArAiCa17-Ch9-BrDb69-BiUCpBqAe19-Ee7-DhDiDdDi93-Fl3BtBz2DxDh3-2Df2Bw104-Bx104-Bz103-Dd102-Cw103-Cd2(103-Dh)3(103-Dx)103-Cq104-Di103-Br104-Bz104-Em2(103-Ei)207-2(Fh103-)Dm102-Dg103-Dg102-Dn103-Em100-FeExFi100-EhFe2Fb99-Ei102-Cz103-Dk102-Fz103-Bd103-Cz103-Ad102-Ai103-Aw102-Ap103-Ar2(103-Bg)102-10(Af103-)2(Ar103-)Dz103-Dw2(103-Cs)103-Ge103-Aq103-Ad2(103-Ay)102-Ay102-Bj102-Cn100-2AhCn100-Ah102-Aw102-Bm36-4S15B3A11BF2EDSHNH3L3GAb3M2J2AoGBs3KP2AoCiH2N2EFE3BFBAB11A15-B103-B102-B2(103-A)3(103-C)4(103-A)102-A103-B2(103-A)103-F2(103-A)102-B2(103-E)103-H103-J103-I103-K103-Ab103-M103-P103-J102-D103-E104-H103-2P104-I2RQEc104-RAl104-R104-Ag102-Ae103-V103-Bu103-R103-Aj104-X103-P44-EpCqDjCqCl55-4JCeXCeO33-Cx2Ep5-ClDu61-3TAl3R3T21-ChCz10-DuEb69-3Bf18-Dy13-Dl71-2En15-Dy15-2Dl71-EnAk12-BdFo17-Cu72-2O10-AqBn18-Cu73-OTR6-2AqBk19-Cz11-Dg63-2R3-AwBmBa21-Cx9-CcDsGf64-Aa2QVBqCp21-Cx9-Cc2Ck92-Fp7-DfBr2-Dt92-FpBj3-BzDiDf4-Cl93-BjBtEr8-3BwDd104-Bx103-Dt103-Db103-Cw102-2(Cd103-)Dh2(103-Dx)104-2(Cj103-)Cj104-Br103-Br104-Ds103-Ei311-2(Fh103-)Fj102-Dg103-Dg102-Dm100-FgDrFi100-Eh101-2Eh102-Ek102-Cu103-Bn103-Fz103-Ey102-Ad2(103-Ai)102-2(Aw103-)Ar102-2(Bh103-)Cp11(103-Af)103-Ar103-Ct103-Ba103-Bp103-Ge2(103-Ad)2(103-Ay)102-Ay102-Bj101-BjBo100-2Ah101-2(Ed102-)Bm37-2DSCr14B3A11B3DN2HAuL2Ab4GAb3MPIAnXMPBsKAnMCiAbL3D2FBF2AB15A16-D102-B103-A2(103-B)4(103-A)102-2(A103-)4(B103-)E103-F103-M102-B2(103-F)103-H103-X103-O102-I103-Ce104-Al2(103-Bs)103-J102-2(D103-)L104-Fy104-AoIAa2Q104-2R104-Ac103-Ag103-Ae103-V2(103-W)103-O103-K104-P43-EpDqEbDjCx56-4J2CeXO2BfAj2AlR25-EeCzDqEq5-2EbDu67-4TO19-Fl12-DuDq70-OEn16-BjDk14-2Do70-EnK14-Bn17-Bl14-Es56-KAk11-At19-Bl12-Dm2Es57-AkO8-AtAy20-Dq11-DmEsEz59-OAj6-Ah22-Dq10-Fm-Fu61-2AlR2AmDw24-Cz8-Cc3-Du90-Dq8-Ck3-Eb91-2Bn4-2Cb5-Du92-FpFoBtFo8-Br2CwDb104-Ck103-Bx2(103-Db)103-Df102-Cd103-Di103-Dh104-Cj2(103-Cd)103-Di104-Di103-Cb104-2(De103-)Eg311-Fc103-Fh103-Fj102-Fm102-Fi100-GbDrFi99-EtGb101-EgEh101-2(Dl103-)Ba102-Ba2(103-Av)103-Ad102-El103-Ai103-Ba103-Ct103-Bg102-Bg103-Bh103-Cp103-Af104-Af102-V5(103-Af)103-Ae2(103-Af)103-Ar2(103-Aw)103-Bp103-Ge2(103-Ad)2(103-Ay)102-At101-DkGh100-2Ad100-AqGg101-2(Bm102-)Bm39-2SCrBF8B3AB3A7BFB2F2D2NG3AbMJAb3LG3AbX2AzOAoMJPAoL2HN3E4B18A16-5(A103-)F103-A102-2(A103-)8(B103-)D102-2(T103-)F2(103-H)103-R102-W103-K104-Az103-X103-I102-L103-N103-E103-2(M104-)O3QDc104-R104-As103-Ag2(103-Bq)2(103-R)103-Ak103-K104-I40-EeCzErEeDo2Ep57-3MJ2CeXO2BfAjBi2AlT23-2Ee7-2DlEb69-2TAjO18-Cn12-DqDlDy70-2Ak15-Cn16-2Ch14-FhFm54-2K13-Bk18-Er12-GvFh-Gf55-2K10-Bd20-Bj11-Dm3-Cj56-2Ak7-Ai22-Ch10-Dm3-Cj58-OAj4-AwAi23-Dq9-Ei3-Cx60-2AlRAmAs25-Cz7-Ds4-Cx90-CnBn5-CbDb5-Eb91-Bk2BoCuCq7-EkCw2BrCg104-Dt2(103-Bz)103-Db103-Br2(103-Df)103-Dh2(103-Cj)2(103-Cd)104-Cw103-Cw104-Ck2(103-Eg)415-Fc103-Dg102-Bx102-Fi99-2DrFrFi98-FeEfGb100-BtBz102-Bn103-Cn103-Aq102-Ai103-Ba2(103-Ap)102-Bh103-El103-Bh103-Ag103-V103-Bg102-Bg104-As2(103-U)102-6(V103-)Ag103-V2(103-Ag)103-Bg2(103-Aw)103-Ai104-2(Ay103-)Ey102-Ey103-Gh101-BlGh100-AtAd100-2Ad101-Aq102-Gy2(102-Bm)40-D4F7B2ACAB2A4BFBFE2DE3SG3MJ2AoML3GAb2MCm2OAxI2LAbGDv3D2F5B18A17-A3(103-B)2(103-A)102-2(C103-)2(A103-)3(B103-)B102-3(F103-)B103-F103-E103-D2(103-G)102-P2(103-I)103-K103-X103-I103-M103-H103-E103-Au103-GJ104-Aa2QAa104-2(As103-)Af104-U103-As2(103-R)103-T103-X104-X38-FlDk4BlEeEq58-2M2FyCe2XAkOBfAj4TAj21-Bt8-2EqDlCz70-Aj2O17-Bj13-2DoDy15-FcFhBr52-2Ak14-Bd17-2Cu12-FhFc2-Ck53-2K12-Bd19-Dk11-Fh4-Cd54-2K9-Ai21-Bj10-Dm4-Cj56-EnO6-Ai23-Bj9-Dm4-Ek58-OAj3-Bm25-Bn7-BxDm4-Ep60-AaZAa27-Bd5-CwDf6-Ep90-GlBd-2EeDd7-Du2-BrCg88-Bj11-CwBr2-Db103-Dt2(103-Bz)103-Cb103-Cw103-Di103-Dh2(103-Di)103-Cd103-Df104-Cw103-Cw104-Cb103-Ck103-Eg103-Ez103-Es207-Fc103-Fh102-Ez102-Fi99-EvDrFbFi98-2Fg101-Ek103-Bl102-Bd103-At2(103-Ai)103-El102-2(Ar103-)2(Af103-)2(Ag103-)2(U103-Ac103-)Ac102-Ac2(103-U)2(103-As)5(103-V)2(103-Bg)103-Bm104-Bc2(103-Ad)103-Ay103-Bk102-Ey102-Ch101-BtDy100-FtBt100-2Ft101-Ad103-Gc101-DzEd102-Bm40-DE2DS5B3ABA7BF3EDN2DL2HAb2MAbM2JMAbM3J2P2CmAzCfAoNLAuHE2BF7B18A18-D103-F103-E2(103-B)102-4(A103-)2(B103-)F103-E102-2(E103-)B3(103-A)102-FD102-D103-D104-S102-Ab2(103-G)103-L103-Ao103-Ab103-Au103-D102-S103-H104-2Gm2W104-Dc104-2(V103-)BqAp103-U103-Ac2(103-Aa)103-T104-Dc103-AjT36-Bt2BoFoBt2BlFl60-2ICe3XAk2BfAj3T3Aj19-Bj8-Fl3Dy19-FcDdBr50-OAk16-Fx13-3Cu15-Fc3-Cb51-2En14-Bd16-BjBo12-Ei4-Cb53-2X11-Ay19-Bo11-Dn5-Cd54-2X8-Ai21-2Bk9-Cb5-Ea56-KO5-Dp24-Bk7-BwDd5-Ea58-OBi2-2Af24-BkBd5-2Di7-Dq59-AmZ28-At3-2Br8-Du3-Db86-AtBdFx11-DfBrBw-3(Db103-)2(Dt103-)2(Dd103-)Cd103-Cj2(103-Di)103-Cd104-Bw2(103-Cw)104-Cb2(103-Em)103-Ez2(103-Dm)103-Fc102-Ew102-Fr98-EvGuEvGtGx98-EsEh101-Cc102-2(Er103-)Cn103-Ay103-Ah102-Ba103-Aw103-Ar103-Da103-Cp2(103-Ag)2(103-U)3(103-Ac)102-2(Ac103-)2(U103-)6(V103-)As104-Bq103-Dz103-Aw2(103-Ah)103-Ay103-At102-Ey102-Bo101-ChCu100-FtHc101-Ad102-Cs102-Ed2(102-Ct)102-Bm42-2NHSB2(A3B)A6BFE2DENAuLHL2GAb3G2MAbMIPIBsAnKAz2AnBsAnGDDvNDvF7B11A2C8A19-2(F103-)D103-B102-B103-A103-C2(103-A)2(103-B)103-E102-3(D103-)B4(103-A)102-2(N103-)D103-G103-Au2(103-M)103-G2(103-H)102-2(D103-)L103-2GmTBi104-W103-Am104-AwArCv103-Ac102-2(Ac103-)Aa103-2OFv2(102-2Dc)37-Bo65-Z36-Fo-BoHc2BtFxFl23-2Ck35-6K3O5Aj2Bf19-Bj8-Cn2Dy18-EsEi2-Dd50-BfAk16-Bn12-2Fp2Bj13-2Eg4-Br51-2Az13-Cy17-BkBn10-FuEi5-Br53-2X10-Aq20-Bk9-2Dt6-Cd54-2X8-Bv21-Bk8-2Dt6-Ea56-XO5-Dp23-AqAt5-DiBw8-Ea57-TQ2AeBq26-Aq3-DfCq9-Ep89-2AtEpCj11-Cj2CdCg104-Cb2(103-Dd)103-Dt103-Db103-Dd103-Cw2(103-Cd)103-Di103-Bw104-2(Bw103-)Br103-Br104-Bx2(103-Em)2(103-Dm)102-Eg103-Fu100-2EoFd98-2DrGuFwEo97-DsGi102-Cc102-Ek103-Er103-Ba103-Ay102-Af2(103-Bg)2(103-V)103-Af103-Ac2(103-Ag)103-U2(103-Ac)103-Q102-Bu2(103-Ac)2(103-U)2(103-V)103-Bq2(103-V)104-Af103-Bq103-Bh103-Dz2(103-Ca)103-Aq103-At102-Ay102-Bo102-Gh100-AdEyBl100-Ad102-Cs102-Bp102-Da102-Dz102-Bm102-Bq44-H2L2A8B2FB2F3E2DDvLAbLGJMJ2G2L3GMI2KAzCmCfAxP2AoJN2EDE8B11A2C4A4B20-B103-F103-E102-2(B103-)3(A103-)A102-B103-Cr103-E103-D2(103-S)2(103-B)103-A102-2(A103-)B103-E103-D103-H102-2(I103-)J104-Ao2(103-G)102-2(D103-)Au103-Ak2(O104-)R2-Z100-RAaZ-Am102-Ac2(103-Am)103-Bi2AcDa102-2(Af103-)W35-Fo2Cn65-K34-Bo3-CnAd2At22-2Db2Ck36-Ak4K3O2AjBfAj3Bf18-Bn8-BdCnGl18-Eg4-Dh50-2AkEn14-Bn12-2BnFpBj13-Eg6-Cj52-Az12-Cy17-2Bk10-Ds7-Br53-KX10-Aq19-AqBk8-Bx8-Cq54-2X7-Dp22-Bv7-Cb8-Cq56-EnT4-Bm24-BvBc3-EbDu10-Ea57-T2AeAp27-BvAdChEb12-Ea2Cq104-Cg104-Cd2(103-Df)103-Br103-Dd103-Br103-Bw103-Df2(103-Bw)103-Br104-2(Cb103-)2(Br103-)Cg104-Bx103-Dg103-Fc102-Fm103-Dg100-Ev2Fw98-3Dr99-DsGi101-Df103-At103-Bv102-Aw103-Ct2(103-Af)103-Bq3(103-V)103-Bu2(103-Ac)103-Be103-Q103-Z2(103-Q)102-Aa103-Q103-Am103-U103-V103-Ag2(103-Af)104-V2(103-Bg)103-Ar103-Dw103-Ba103-Ca103-Av103-Aq102-Ad103-Ay101-CnBo100-BnFo100-AqAd101-Bc102-Ar103-Ap102-Bh102-Dz102-Hf102-Cv18-Ay26-2L7B4F2E2DE2DHNDvL3M3Ao2G2L3GJ3AzCmAx2CfAbCiGAuFB2F5B21A4B21-B102-F2(103-E)103-Cr3(103-A)102-2(E103-)B2(103-E)2(103-S)103-B102-B3(103-A)103-M102-2E102-E104-D102-Fn2(103-E)103-G103-L2(103-E)103-D102-H104-G2(104-Ab)-2Z100-2X2-Ak5-CqDx96-Ak5-EeDx95-R5-AdCz96-Am-2AsCpAd98-2Bi2-Da102-Da2(103-Dc)34-Bn2BdFz26-BxBy37-K5-2O2AjTAj21-2Cn4-AdAqCy21-EaBr2-Bz37-2K2XAk6-OBf2Aj16-Ay9-AqAd17-DiDx5-Dh51-2Ak14-Ay11-2GlBnAt12-BwBz7-Cj52-Ak12-Av16-2BkAd9-Bw8-Ea53-2X9-Bc20-2Aq7-Cj9-Cq54-2X6-Ca23-Bv5-DxCj9-Ea56-XT3-Ap25-AiBcAi2Ch12-Ea57-BiAeDw44-3CqDf104-Df103-Cd2(103-Df)103-Cw103-Br103-Cw103-Bw103-Df2(103-Bw)104-Br3(103-Cb)103-Cg103-Bz2(103-Dn)103-Ew102-Dr101-3Gu98-2DrEx99-CcDs101-Cb103-Dq102-Ay103-Ai2(103-Ct)103-Cp103-Ae103-Ag2(103-V)103-Ac2(103-Bu)103-Aa103-Be2(103-Q)103-Be102-2(Be103-)Q103-Am103-Cv2(103-Ag)104-Ae103-Af103-Bh103-Bg104-Bg103-Ap2(103-Bm)102-2(Av103-)Aq102-Ay101-2Bn100-BkCn101-2(Aq102-)Bc102-Ar102-Da102-Bh102-Cp18-CaBo82-Ag18-BmCaDk81-Cv18-Ff-2Dk25-NDSDF3BF2E4DS5HAuAb3M2(AoJ)MAbM2(JP)4KBs2AnAb2AuDv9B7A2(C2A)C7A4B21-B103-E103-Cr2(103-B)2(103-A)102-Cr103-E2(103-D)3(103-S)103-D102-E103-B3(103-A)103-C103-A102-B2(103-F)2(103-E)103-D103-E103-F102-F103-B103-D103-G104-L10-CjBz92-Ab2-Ak6-Ea2Bz91-2XG-Ak4-Cq2-Bz95-Ak4-Cj2-Bz95-I2-CaCz2-Dy96-2BuAe2-BoBj101-Bt102-Ec103-Ac33-At69-Dc32-Cn-Bd2Ad24-2BwCgCd38-KX2-4OBi3T20-Fx5-2Bc20-DiEk4-Df39-2X8-2AjT16-Bd8-BvAiBv16-Di7-Cj51-2O13-Aq12-Ad2Aq12-Cd9-Ek52-AkX11-Aq15-2CyAh9-Df9-Ea54-X9-Av19-AwCsBp5-CjDi10-Do54-2X5-ArAp23-3Ai2DoDx11-Do56-AjBi2-Ap43-Cx3Cl54-2Al48-Cw104-Df103-Dh2(103-Cd)103-Cw103-Br103-Cw103-Bw2(103-Df)103-Cw104-Dd4(103-Cg)2(103-Bx)103-Fc101-2Ex100-3Ex98-4Ex99-CcFm101-Db102-Dl103-Cu103-At103-Ai103-Aw103-Ar103-Cp103-Bq2(103-U)2(103-Ac)103-Am103-Q4(103-Be)103-Z102-2(Be103-)Z103-Am104-U103-Ag103-Bq103-Ae104-2(Bh103-)2(Bg103-)Ap2(103-Bm)102-Ai103-Ah102-Gl102-Bk101-2Bk100-2At101-Bc102-Bp102-Dp2(102-Bg)18-EyAh82-Ae18-FjBdBk82-Ae17-Fc2-Bo81-Ag18-Es2-2Dk79-Cv18-Es3-DkBo24-DSFn4FEDE2S2N3HLAbM2Ab3M3JAoP2AoBsPBs4AnAoBsJCiDNDvE6B10A4CA2C3A8B22-B2(103-Cr)2(103-B)103-A102-A103-B2(103-E)2(103-D)2(103-S)102-D103-F2(103-B)2(103-A)102-C103-A2(103-B)103-F102-F103-F104-E102-4(F103-)D103-Dv10-CgCb92-L8-Cj2-Bz91-M7-CuEk3-Ck90-3MJ4-CuCl3-Bx94-P3-Ea4-Dd94-P-AgV4-Do96-Bu5-Hc101-BdBj101-K102-Z33-AdBv27-2Dx39-R32-Bd2-AvBc22-ClDuCq2-Di39-2PI2Ak2O3Bi2T19-Fx5-BcCs19-Dx6-Cd50-2T16-Bd8-BpAi16-Di8-Dx51-2Bf13-Aq11-Bv2Bc12-Cq9-Dx53-BfK10-Aq15-Cs2AiCs7-CjBw10-Eq54-K8-Ct20-2AwEl3-DoDj12-Eq54-K6-Ar24-Ca2AiCa14-Cx54-KT2Bi2As44-3Cl104-Di104-Cd103-Dh103-Cq2(103-Dh)2(103-Bw)103-Cw2(103-Dd)103-Dt2(103-Cg)103-Em103-Bx103-Dt103-Cg103-Fu102-2Fd100-2Gi99-DmEfEx100-2(Br102-)Fp2(103-Ay)103-Bc2(103-V)2(103-Z)103-Am2(103-U)2(103-Ac)103-Dc3(103-W)103-Aa103-Q103-Z103-Ac103-V103-Bq2(103-Ag)103-V104-Bq103-Bh103-Ap104-Ba103-Dz103-Bp102-Bp2(103-Ca)102-Bv102-Ft102-Bk101-2Bd101-At102-Ca102-Cs101-UBp102-Am18-Bp83-Am17-CgAhAv82-R17-Dg2-AdAt80-Ae18-Fj2-2Bd79-T18-Es3-BkAq78-I19-Fj4-Fp78-O19-Fj4-Bo24-LFnSEFE3DN3HL2GAbJM3J2M3JPBs2I2KAzK3IGAuHNDEF5B12A7C3A8B23-F2(103-Cr)2(103-B)102-2(A103-)B103-E2(103-D)103-S102-S2(103-D)3(103-B)102-4(A103-)2(E103-)D102-2(F103-)2(E103-)F3(103-B)9-Cg93-B7-2Dl-CgDb91-AuM4-2CtEd4-Ck91-AbM2Ce2ArEd6-Bx90-AbJAbP2AeCp6-Ck93-PBu2Bq6-Ck94-BuBq6-Db102-Eq101-AdDy101-Aj102-Aj32-AqCs25-ClDu2Dx40-P31-Ad2-DpAwCs20-ErCq4-Di40-GIK3Az2TAl2Bi19-Ad6-Aw17-2Ek7-Cd50-2T16-Av8-CtAw14-2Ch8-Cl52-2Bf13-At11-2Ba11-CuCh10-Dj53-OAk10-Bc14-AwCsDwBmCt5-CuBl12-Eq54-K8-Ct20-ArApAr2CsBn14-Eq54-K5-2Ar42-Dq54-KBi2AlBi45-3Cl104-Di104-3(Cq103-)Cj103-Dh2(103-Bw)103-Br103-Dd103-Dt2(103-By)2(103-Cc)103-Bx103-Bz102-Dn102-FdEf100-2GiFd99-Gf2Gi100-2(Cc102-)Ay2(103-Bp)102-Bg103-Cp104-V103-Am2(103-Z)2(103-Dc)2(103-R)103-Bi103-Aj2(103-O)103-T2(103-Q)103-Ac103-As103-Bq103-Da104-Bh103-Ap103-Aw104-Bm103-El103-Ba3(103-Bp)102-Ca103-Ca2(102-Bc)102-Ay102-At101-AyAt101-Dp102-Cs102-Ed18-At83-U18-AwBk82-Am18-Ck-Bk81-W18-Eg2-At80-Al19-Eg83-Aj18-Ei83-Bf19-Dn82-Ce19-Fj83-Ao19-Fj29-DAbS2DEDN3H2AuGAbGM8JPAoP3BsAn2KBsJAoJH3D4BAB14A5C5A8B24-2(F103-)B103-B102-A103-C103-A103-B103-E103-D102-S2(103-D)103-F2(103-B)102-2(B103-)A103-B2(103-A)103-E102-B2(103-D)103-E2(103-D)103-F103-B103-A102-B7-Cu2DdCg92-DB4-AhCn4-DbBz92-J2ODw8-Bx103-Bx104-Bz103-2(Db102-)Ek101-2Dy101-Aj102-JI29-AdAvCs23-DlDjDuEkCx42-Ab29-Ay3-Ba2Aw18-2Ch5-Cl42-PI2XAzK4Bi18-Ah7-Ap16-Eq8-Ep51-2Bi16-Ah8-Da13-2Ch10-Ea52-TO13-Av10-2ApBa9-2Cu12-Cx53-O10-DaAr14-Af2DwBm3ApCaEeBt14-Cx53-AzK7-Da41-Cx54-K4-WAr43-EbEa53-O3Al47-2DjCq104-Dj3(103-Cq)103-Dx103-Dh103-Cd103-Bw2(103-Cb)103-Dt103-Bx2(103-Em)102-De103-Ck103-Dt102-Ef101-2Fd100-FmGi100-2Dn101-DlCc102-Dy103-Bn102-Ai103-Bm103-Ar103-Cp103-V104-As103-Z103-Aa103-W103-Dc2(103-R)2(103-Aj)2(103-O)2(103-Dc)103-Z103-Bu103-U103-Ag104-Bu103-CvAf103-Ap103-2Ap103-Ct103-Dp3(103-Bp)102-Bp102-Ca102-Ai103-Bc102-Cy101-AdAy101-Ay102-Av102-Ed102-Ct17-Ch84-Ct17-Em84-Cv17-Ck84-Cv18-Ck83-Aa18-Eg83-R19-Eg82-Aj19-Ei83-Ak19-Bz82-Ce19-Bz83-P19-Dh31-2SDS3HL2GL3G4J2PIPIBsAn4IAo2PJLGLDv3E3B2AB15AC7A5B4A25-D103-B102-B2(103-A)103-C103-B102-2(E103-)S3(103-D)2(103-B)102-6(B103-)B102-E6(103-D)102-2(B103-)A103-A7-2BrBwBr92-DIKAz2AvCnAv4-2(Ck104-)Dt103-Bz103-Dd102-Cg103-Dq102-Gh101-CaGh55-Cx46-Am28-AqBc2Dw21-ChCzEb-2Dq43-K28-Ay4-2Ap16-2AtCh6-Cl43-3I2K2TAlBi18-Bv7-Ag14-ErFx9-Ep51-2Al15-Ai9-Da12-Ee12-Bl52-AlO12-Dz11-AgAf9-Cx14-Cz53-O10-Da14-2AfAeBhAe2AwAvBc16-Er53-X7-AeDa41-Dy53-XK2-AlRW44-EbEa2Eb51-AlT51-Cq104-Dj2(103-Du)103-Cq2(103-Dh)2(103-Bw)103-Dd103-Cg103-Bz103-Bx102-2(By103-)Ck103-Ck102-Ef100-Et2Ef99-Dg2Dm100-2Ei101-Db103-Bl102-Ag2(103-Bp)103-Da2(103-Ae)103-V104-Ac103-Be103-Aa103-Al103-R103-O3(103-Aj)103-Ak103-Bf103-Aj103-Dc103-Z104-Bu103-Ec103-Ac104-V104-Ae103-Bh104-Ct103-Bp103-Cs103-Ca2(102-Bp)103-Bp102-Ca102-Ai102-Bc102-Cy101-BvAh101-Ah102-Ar102-Fv17-Ck84-Bh17-Bx84-Af18-By83-Cv18-By83-W19-By83-T19-Bx82-T19-Dd83-Bf18-Dd83-K19-Dx83-Ao19-Dx83-S18-Cl32-3SHL8GCi3JPAnI2AnKAnI2PICiGAbLE2NECrF2B4AB19A6BAB5A26-N2S101-EDv101-2B102-A103-B103-C102-2(B103-)E2(103-S)2(103-E)102-6(B103-)B102-2(B103-)E4(103-D)102-2(D103-)2(B103-)A103-D8-BwCd93-KIAzAvApCaAvAyEb2-Di104-Cb2(103-Cg)104-Cj103-Ep102-Bt102-Cn102-Dz27-Aq25-ChEe47-Z27-Ad-2DwFv18-CnBo2Cu2-EeDq45-Ak27-At4-AfBq15-Bj8-Ch45-PAo2IAjTBi19-Ad7-V12-EeCz10-Bj51-AlBiAl15-Ai9-Ag11-Do12-BtBl52-2Ak11-DaDz11-AgBu7-AvDo15-Bt53-En9-Da15-2WAcAg2AeBh18-Bj53-X6-AeDa42-Bj53-2XKAlWR45-FlDl2Dq104-Eb104-Ep103-Eb103-Ek2(103-Cj)103-Dh103-Bw103-Dd103-Db2(103-Bx)102-Bx103-By102-Ck103-Ck102-EfCk100-Gb2Ef99-DmEt101-Es102-Bt103-Bj102-2(Bh103-)Dw2(103-Z)103-R103-Bi103-Al104-2(Bf103-)Ak2(103-X)103-O103-X2(103-I)103-X103-Bf103-T104-Dc2(103-Ec)104-Q103-BuAc103-Ag103-AeAf103-Af104-Av103-2(Bc102-)Ai103-Ai2(102-Cs)102-Aw102-Ai102-Ca102-Ah2(102-Ai)102-U102-Ae17-Bx84-Bh18-Bx83-Dc18-By83-Ak19-By82-I19-By83-I19-By82-O19-Cg83-I19-Df83-H18-Cj84-2D17-Cq84-2D16-Cq35-2GAbG3MCi2GAoP2JIKAnK3AzIAoJAoL3N3E4B5AB7AC3A2C4A8B5ACA29-2H101-2Dv101-2D101-2B102-B102-F103-E103-B103-E2(103-D)103-F102-F6(103-B)102-3(B103-)E102-D103-D104-D102-G3(103-D)2(103-A)103-J7-FoEq95-2WApBg2AwEe2-Eb104-Cb103-Cg102-Cj103-2Dx103-Dx104-Ep102-Av102-Af26-El22-GhBlDkBlEe48-Bu26-Bc-2AfFv16-2FlBt5-2Bl46-Ak25-Bc5-2Af13-ChEr9-Bo46-2KO3Aj18-Bp8-Ac11-Cz12-Bj51-Bf2O14-Ap10-Ac10-Cz13-2Cn52-K12-Da12-AmAa6-AdEy16-Bn52-En9-DaBg15-2W3AsU19-Bn52-2K5-WZ43-Cn53-3XTW46-EeEq2Dq104-Dq104-2(Cx103-)Ek2(103-Cj)103-Cd2(103-Dd)103-Db102-2(Bx103-)Bx102-Bx103-Ck102-Cc101-2Fg100-FfEh101-Eb102-Bn103-Cy102-Dp2(103-Bh)103-Ac103-Q2(103-R)2(103-T)104-2(Ak103-)3(X103-)4(I103-)I104-K103-Dc103-Aj104-Al103-HgAa103-Z104-Ac103-V104-Bh103-Av2(103-Ah)102-Av102-Ai102-Ca2(102-Cs)102-Bv102-Dp102-El102-Bh102-Af102-As102-Cv103-Ac17-Bz84-2(Dc18-By83-)K19-By83-J19-By82-AoD18-Db83-ME17-Db84-ME17-Cz84-E2D15-Cz86-2D15-Cq86-DSD13-Dj38-M2JAoJ2(AoP)I5AnJBsIJAbAuLHNDvD4B8AB7A3C4ABA9B4A3C31-NHL100-3N100-2D101-2ES100-FE101-2F102-3(D103-)D102-3(F103-)B103-B102-A3(103-B)103-E103-N102-F2(103-E)2(103-D)2(103-N)103-D103-E103-A103-B103-NL5-FoEb97-2AsZApGl2-Du103-Bw2(103-Cj)2(103-Cz)104-Cu103-Ca103-Af24-2BpElAf17-Gh2FlDkBtDkBl50-Q24-Bc4-2Af14-Ch7-BtBo48-K24-Ai6-Am12-Ch10-2Bo47-Ce22-Bp8-Am10-Bl13-Fx47-4KEnO14-DaAp10-BuZ8-Bl14-2Cn51-2K11-Bg14-Aa3-2AeArBd17-Bk52-X8-AmBg16-2DcAs22-Bk52-CeX4-2W44-Bk53-3KAk47-BlErEeCz104-Dq104-Cx103-Eb103-Ea103-Cl103-Cj2(103-Cw)103-Db102-Bx103-Ck103-By103-2(Ck102-)Ck101-EhFe100-EwEh101-Eb102-Dy103-Bd102-Ai103-Dp103-Ap103-Ag2(103-Q)2(103-R)103-T104-T2(103-Ak)2(103-X)5(103-I)104-Ce103-X104-Bf103-2Aj103-Aj104-Be103-Z104-Bh103-Da104-Bv103-3(Ah102-)Av102-Bc102-Ca102-Bp102-Bc102-Ba102-Bg102-Bh103-Ae102-V102-Am102-Cv103-Ac17-Cl84-Dc18-Dh83-Dc19-Dh83-B18-Dh84-2B17-Dh84-DB16-Ep85-2E15-Bj86-3E14-Bj87-ED13-Bd88-4D11-Bj89-5D8-Ad40-J2(AoP)KAz2CmAnBs2IJMCiL2AuLDv3E4B16A3C4A8BAB5A3C34-2GAo100-H2L99-2NHAu100-SN100-FDS100-2BF100-2B101-2E103-E102-3(F103-)B103-B102-3(A103-)3(B103-)N102-F103-E4(103-D)2(103-E)103-F2(103-B)103-LBiR-Ap2BvAt99-Bi4-2(Bl103-)Bk102-Ey103-Ey104-Da103-ApAi104-Bh45-BlDkBj54-U24-AiBpBmAf16-FpBl3-Bj2Bn51-Bi23-Bc4-2Af13-Ch8-FtAy49-O22-Ai7-ZQ10-Cu11-AtAy47-Ce21-Cs10-Q8-Bo14-Bd47-2K2IJFy14-Bg12-Be6-2Aq15-AtBd51-AoI10-2Bg14-2AlAaUBgAf19-Bd52-P7-2Aa42-Bk52-PX2KAz2W45-BkBl104-BlChBl104-Cz104-Eq2(103-Dl)103-Ea103-Cj103-Cw103-Bz102-2(Cc103-)By103-By102-Ck102-Bz101-EwFf100-EwEh101-De102-2(Dy103-)Bd102-Ai103-V103-U2(103-Q)103-Bi103-Ce104-2(Bi103-)Aj103-O103-Az103-Ce4(103-I)104-I103-IX103-XCe102-2X103-Bf104-Be103-Be104-Ac103-Bq104-Ct103-Bv103-2(Av102-)Cs102-Av102-Aq102-Ag103-Ag101-BuCp102-Ag102-Af102-Al102-W102-Aa103-W102-Am102-Ac103-M102-DE17-Ea84-BE17-Ea84-3A15-Cx86-2B15-Dl86-2B14-Ch87-FBF12-Bj89-4E10-Bj89-DE2DED7-Fx92-2DEDG6-Ay94-ENGX4-Ad43-AzAn2OCmAxAzP2IHAuHS2(DE)BF5B13A6C3A8B4A7C37-GPK100-LP101-2L100-SHL100-DSN100-2D100-2BED99-3BD100-3F100-E2DS100-FE102-F103-B102-3(B103-)2(A103-)B103-B102-2(B103-)F103-S102-D103-D104-B2(103-E)103-F102-2(B103-)EJAkOApBvBqAt104-2(Bl103-)Bk102-Ey104-Da103-Hg103-Cv104-Ct24-ElCs18-2DkCuDk56-Dc22-Bc2-Bm2Af14-Fp4-FpCn2Bn52-R21-Ai6-AfZ11-Dk9-FtAy50-Ak20-GcBa8-Q9-Bo12-AtAy48-I19-Bh11-Q7-Ai15-HnAd47-PIJG14-Bh13-R4-DzArBv17-Ay50-2GFy9-AsBg15-3AlAe21-Bd52-P6-2Aa43-2At51-AoCe2KAzBi47-Bn104-3Bl104-Cz104-Eq2(103-Dl)103-Ea103-Cd103-Cb102-Bx103-De103-Cc103-Ds102-Ck103-Ck101-FkFe99-Fc2Fh100-Ea103-Bj102-Bk103-Bm102-Af103-V103-Q103-Al2(103-Ak)104-X2(103-En)2(103-T)103-Bf103-K3(103-I)104-I2(103-2I)103-CeX2(103-T)103-BfDc102-Bf2(Z103-)Ac104-Ct104-Aw102-Bp103-Av2(102-Cs)102-Av102-Aq102-Dw2(102-Ac)102-Q102-Al103-Al102-O102-X103-P102-Bf103-DY102-2Y102-2C15-Ea86-2C15-Ea87-2A13-Cx88-2A13-Dl88-4B10-Cz90-2FE2D7-Dk93-E2DFn6-Dk95-Au2G4-Fx97-2PT3-At98-XT2-Aq46-O2BbAzJCiMDDvDE2F5BA3B6AC6A2C4A11B3A8C40-KAn100-3Bs100-MPBs100-HLM100-NHG99-2DN2(101-DS)101-2D102-HG100-2EG100-3E101-BCr101-NB102-B103-N102-A5(103-B)103-F102-2(S103-)2(L103-)2(E103-)Fy103-H103-Ab103-JLXZU2BqAw104-Dp102-ApAe2Ap100-ApAeUAp100-V2UBg100-BuAaBuV100-Hg2Bu102-R103-AeCt22-2El2Dz16-BjDkFoBt58-DaAr19-Bm4-3Ae12-Fo4-2BoAt2Ay53-Aa20-Ct7-Q10-Bo10-3Ah50-Ak19-Ap9-Q8-Bj14-Cy49-I18-Bh11-Be6-Bv16-2Aq47-2PI14-AgBh13-AlDc2RAeDz19-2Aq48-3GCi9-Aa42-At51-2M4-R2Aa44-Ay52-Ce2KEn48-2CnBo104-BoEr104-Cz103-Do2(103-Dq)103-Ek103-Cd103-Dt102-Bx2(103-Em)103-Ds102-Ck101-2Fg100-DgFh100-ChDd102-Bj102-Hn103-Av103-El103-Af102-Ac103-Q104-Al103-Aj103-K103-I2(103-Ak)103-T2(103-Bf)103-K103-I104-I103-2(3I102-)IKAl102-OAl103-AlR102-2R102-DcR103-Aa103-Bu103-V103-Ae104-Ar103-El2(102-Bp)102-Cs102-Cy102-Bc102-Bg102-Ag102-Cv103-Ac102-Be102-Al103-Bb102-Az103-Az102-BE102-2Y103-Y103-2Y102-2C13-Eq88-CAC12-Bo89-4B9-Bl90-3B2F7-Do93-F3E6-Ay95-2NT4-Bn97-H2Z3-Bo98-2Am2-Ap100-BaEdCs101-AiAvAh49-AoJCiGED2E4B11A3C3A2C7A8BA2BA10C42-AnK2J99-CfAzK100-2AnCo100-I2An100-P2Bs99-NG2Bs99-2NP100-S2N100-NSH101-AuL101-3G100-SGL100-CrSH100-Cr2F100-A2B100-D2AB100-FA102-F103-A2(103-B)102-2A102-7(B103-)Fy2(103-E)103-2L2R2BeUBg104-2BaAw103-Bm103-Cp2(103-U)102-Ac6-EsFf94-Ac5-Df2CcDg94-Ac2Am-AfDyBz2Cc14-BgAr2BgAe14-2Bj2Bn61-ArBt17-Bm5-AeV11-Fo4-BkBoAdBv2Aq54-Ar18-Ap8-Am9-Bo11-2Ah2Av49-KCp17-Da10-Q7-Bj16-Aq49-Cp16-Ae12-2Be2QZ2Ba18-CyAh47-JFy13-BuAe40-Aq48-4G7-2W43-Cy51-2M2-2KR46-AqCn51-2K51-Cn2Bn104-Er104-Ee103-Do103-Dq103-Cx2(103-Cd)103-Dt102-2(By103-)Cc103-Ds101-FgFu99-2EgDg100-Dl102-Ch103-Ad102-2(Av103-)Dw103-Ag103-Ac103-U103-Bu103-Aj103-Ak103-Ce103-Ak4(103-Bf)104-P2(103-2I)2XR2Aa99-I2RWAa100-2RWR101-2WR101-2R2(Al102-R)103-Hg103-Q2(103-U)103-Af103-Ar102-Cs102-Bm102-Cs103-Bc101-AwAv102-Bc102-Dz102-V102-Cv103-Ak102-Be103-Be102-Aj103-Au103-2Y2(102-HsY)102-2Y103-2Y102-2C2A9-Bn91-4AB7-Bo93-B2FL5-Ct95-CrOKO3-Ct97-3OAj2-Ay98-TZBeAeEd100-Ae2Bq101-BhBgAg258-GL2EF5B11A3C2A3C4AB2A8B4A6C2ACA46-2N100-2AxAu100-Ej2Ax100-2FqEu100-Ec2Fq100-2XFq99-2CeX100-G2Ce100-HLAo100-2Fn102-2Ab101-HPK100-DHN100-2DE100-2EB101-BA100-4A99-4A100-C2A101-3C101-2C102-2A101-3A101-3(2B102-)B103-3(2A102-)2B102-FE103-K2BiAl2UAsUAe104-Ap2(103-Bh)102-Ag103-Q5-2Ep96-Am3-CzCu2-Gu94-Ac2-ZAp4-Gb12-Bg81-AlZAf5-Bz11-AlBq-2BgBh2Ae12-BdFz2Bk64-AyBlClDi11-BuAa7-AeAc9-Cy4-2AdBc2BvDpAi2Bv53-2BvCy14-Bu10-Z7-Bo14-BvAv51-Bh15-Ag12-Z4-CaBv17-2Av49-Cp14-U14-ZAm2Z21-AhBc47-Ak12-WAa42-Cy47-G3L6-RW45-Cy50-2LFy3X48-AhAt104-BnAt104-Bt104-Ee103-Eq103-Ea103-Du103-Dh2(103-Bx)103-Dn102-De103-De102-Ew100-Ds2Ew100-Dd102-Dl102-Bd2(103-Ad)102-2(Dw103-)Ac2(103-U)2(103-Bu)103-Z2(103-Be)103-AlAk3(103-M)P5-W97-3IBi3WAm97-2ITBi2AaAc103-Bu103-Ac103-Bi103-Dc103-R103-W102-2(Q103-)Am103-U102-U103-V102-U103-Cp102-Bm102-Am102-Ar102-Am102-Bi103-Bi2(102-T)2(103-Ak)102-2(N103-)2Y103-Y103-2Y102-3Y101-2Y2CA100-2C3A101-4AE4-Bn96-FDAzR2-Ad98-GAzBgAw-Gy99-KBgAwDz101-BhBa103-Ar468-2F5B11A3C3AC4A9BAB4A7C4A48-2B101-GL101-KBs101-CoCmO100-FaCoAx100-2FaAx99-3FaFq99-2IEu100-J2I99-GM2J100-2AbG101-2TJG99-HNG100-D2N100-BEF100-A3B100-2AB100-3A100-2AC101-3C100-A2C101-3A101-2A101-3A101-2B102-2B101-2A2(103-A)2(103-B)103-LICe2OAa104-ZAe104-Cv2(103-Bq)103-V103-X4-Cu2Eg95-Z2-CaBtCu3-Ex94-2OAa6-Fk8-AlWBm5Ae86-Ez8-WR7-Ae11-Ai2BdEyBc67-CjDg9-Q9-AsAc8-Cy5-2AiBc3DpAiBv2Bc55-CqCl11-Bu11-Z6-Bc16-2Bv51-DaAp12-V13-2Z2Ac2Ca19-2Bv49-2U11-2U40-Ai48-Bi10-2W43-Ai48-MFy6-2R46-Ai49-2L2AbCeX49-AhAtAdAt104-Bo104-Cu103-Er103-Do104-Cx102-Cj103-Di2(103-Bx)2(103-Dn)102-Eg100-GfEhFg99-CcDe101-Bn103-Bn102-Aw103-Bm103-Ae103-Ac102-Aa2(103-Ac)103-Ag103-Bq103-V103-UAa103-L2G101-LGAb102-3Ab101-2Ab2K2-TQ96-M2JBi2RAlZ97-2J2BiR-BuZ2(103-Am)3(103-Ac)2(103-W)102-2(W103-)Bu102-Am103-Cv103-U102-V2(102-U)102-Ac103-Am102-Q102-Bi102-O103-O102-Ce103-Ce102-2(H103-)EC102-YGj103-2Y102-3Y102-2Y2A101-Y3AB101-2A2S101-ADKQRAcAh99-AmBh2ArAd100-AwElAw102-El781-H4B11A3C8A8B4A10C4A50-2FB100-E2F100-BsLS101-OL101-AxAz101-AxCf101-2Cf100-2EuCf100-2BbEu100-HhGzBb100-GCiGz102-CiGr100-MXBf100-3J100-GM2J100-FGJ100-ABL100-3A100-3CA100-CA101-C2(2A101-)3A101-AC101-2C102-AC101-2AC101-2C102-2A102-2B102-BE102-FAb2OJAaAl104-Am104-Ak103-O102-2(I103-)X3-2Ay2Bz96-2O2Ae4-Fk8-ApDwCt92-Eg6-AfT3-3AeBqAe13-At73-Cc6-Bu9-BqAg10-Ai-EyAyBc69-Cc7-Bu11-Am8-Ai5-AiBpCaCs3BaAiBc2Bv56-DjEz8-U12-Z5-DwAi17-AvAh52-BoDk9-Ag14-ZBu2UAg21-Ah51-Ct9-Q42-Bc49-2V7-AlAa44-Bc49-AjAl4-2I47-BcAv49-L2AbCe51-3Ad104-Bt104-Cu103-Er103-Ee104-Cx103-Du102-Br103-Db103-Cc2(103-Ei)99-DsEhEtFc99-Em102-Ep102-Bl103-Bj102-2(Bm103-)Ae103-Am2(103-Q)103-Cv2(103-Ak)103-Ab3G101-2GAbP102-AbIK101-2M2K2Al99-J3TAlZ99-2T2-Z103-ZCv2(103-Am)3(103-Ac)103-Q103-W102-Aa2(103-Be)102-Bu103-2(Ac102-)Cv103-Cv102-U102-Ac102-U102-Q103-W102-Bi102-O103-O102-Ce103-G103-HA102-2A103-GjC102-2Gj103-Y2GjC101-Gj3ABCr100-ABHDEHg100-FnAb2GmAc100-2KTCp1199-3B9A3CAB3A11B3A7C8A53-3B100-F2B100-2DE100-N2S100-HDvD100-AbDF100-CmLD100-KCmI100-AnGrAnCi99-CmFyGr100-2Gz102-Gr2I100-R2Hl100-J2Cm101-2O101-GOAx100-L2Ab100-2NH101-2D100-CAE101-2AF100-2AB101-2A101-3A100-C2A101-3A101-2A101-2CA101-2A102-2B102-ED103-3J2Al104-Al103-Ak2(103-I)102-J103-J2IAgAyCj104-BwDf7-2ArApDwBg3Ae88-Di6-Af8-2Bq13-AdAy71-Eg6-Cp10-2Ag10-Ai2-AyBc9-Bv59-Cg6-Cp12-Z7-2Ai5-BpAwBaCsBa2Aw2Bv-2Aq56-Cj7-Ae13-Z4-VAr19-Aq54-Dy7-Bq15-Z2AcU22-Ah52-Ba7-Q43-Ah51-V5-2Al45-CyAh49-2AlG2PI49-2Av104-2Ad104-Bt104-Bl103-Dy104-2(Cx103-)Di103-Cg103-Dd103-Ck102-Eh100-EtFgFe99-BzDs101-Hi103-Ah102-Bj2(103-Ct)102-Ar103-Ae103-U2(103-Ae)2(103-X)103-Ak3GM103-2AoP102-3IAl101-2KAlBu103-2Bu2(103-Q)831-2(W103-)W102-Be102-Am103-Q102-Al102-Cv103-3(Ac102-)J102-R103-R102-Al103-K102-K103-SA102-SA103-2A102-3A102-3C2A99-Y3CA2B100-GjA2BEGz101-2CrAs103-As1409-3B7A3CA12B3AC2A7C8A56-AC101-B2A100-2FA100-2(DE101-)FD101-BF101-A2B101-B101-2Ci100-Gm2Ci102-2Gm101-2CmHt100-GdAnCi100-Ax2Gd101-AxO101-CmO101-P2X100-2DP100-E2D101-2E101-3B100-3B101-3B100-A2(2B101-)2AB2(101-2A)B101-BFE101-2N103-PX2K104-O2(103-I)102-P2(103-M)KArAw10-BmDzAr91-Dy8-Ar3-ArBg2AeAg87-Eb6-DaAm8-VAs13-Ah72-Bj5-Da11-U10-2Ai-2AvCa7-3BvAh58-Bj5-Af12-2Z7-Ca6-El3AwElAwBa4-Aq56-Bn5-VAf14-2Q3VAgAr19-Ad55-Bn4-TQ42-AdAh52-Cy4-AzBf45-Ah51-Am3-Az48-Aq50-2JMP50-3Ad104-AdFz104-Fo103-Dk104-Ch103-Eb103-Dx2(103-Cg)103-Br103-Cd101-EwEh99-Db2Ff100-Fl102-Ah103-Ah102-Bm103-Ct103-Bg103-Bq102-As103-U103-Ae103-Bg103-2M103-3LG104-2JPBiW101-IBiV103-VAa103-Aa1351-O102-K103-K3(102-Ak)103-K102-I2(102-J)103-Aj102-L103-G102-KGB101-3A102-3A101-4A2B99-4A2BD98-4ABDHu100-2AHuGz102-BiHy1724-2(AB)3A3CA11B4A5C2Y3C8A58-2AB2(101-2A)100-2BA2(100-3B)100-3A101-2A100-3A100-B2A100-Hp2B101-NB102-HvFA100-CiHpB100-2GnCi100-K2Gn100-CmOAn101-2An101-PIK100-2JP100-2SH101-2S101-2BF2(101-2B)101-3B101-2B101-3B101-BCr102-HD101-EHD102-2IP104-J2(H102-)2H102-H103-Ak103-IBh10-BuVAe2V2Gp87-Ac8-W7-As87-Q6-As9-2VQ13-Bc71-Dk5-Cp12-U10-AiCa-2BcCaEl6-BpBcBvAv57-Bd4-ZAf13-2Z6-ApBp7-3Bm3El4-Ad56-Aw4-T16-AaQ2V2Ag20-AdAq54-Ae3-Aj45-Aq53-Ae2-O47-Ca52-2MK49-2Ad104-3Ad104-At104-Fo103-Bt104-Ch103-Ep103-Di103-Db103-Cg103-Cc101-FhEt100-DgFh101-Db102-Bj102-Ah103-Bc103-Bm102-Bm103-Ag2(103-U)103-Z103-Bb103-LG103-2GM2JAoBf100-M2JBfGk104-T103-W1559-En102-K103-2(K102-)Ak102-AkI102-J102-GH101-GND101-2DE100-F3E100-4F100-5B100-2(6B98-A)5B101-2BHz103-Hv2039-P3AC3A10B2A6C4YC10A61-A2FB99-4B99-3B100-A2B100-2C101-AC101-2A2(101-CA)101-2A101-2B101-AF103-A102-2B101-DF101-2Ci101-AnICi100-Az2(2An101-)PAn101-2PI100-2ES101-FE101-2FE100-3B101-BF101-2BCr101-BF101-2BF101-DE102-2D102-D2G104-2(S102-H)2(102-2H)102-DpW8-UBu2VUVCvAc87-Bl6-KR8-As87-Bt5-Al10-AcZQ12-2Ai71-Bj3-2Al13-Q9-2Ai2-2AiDpBm5-Aw3AiAv57-Bd3-R15-2W6-Aw8-2DwBmCtAw5-2Aq55-Af2-AjT17-RAlW3Ag21-Aq54-AfAb2I46-Bc53-QMJ48-Ai104-AqAd104-3Ad104-At104-Bo104-Fl103-Ch103-Dl103-Di104-Db103-Cg101-GvDg100-CkEm101-Db102-Dj102-Bl102-Ah103-Bc103-Dw103-Ag102-Q103-R103-U2AbI100-XGAbJ2P99-2LJAoJIAk98-5J2O103-OBf103-Aj1767-Az103-J102-PAb101-3G101-AuGS101-SND100-3DE100-2D2E100-D3E2(100-4E)100-4F101-F2B103-B2458-2A10B4A4C3Y4C9ACA65-2B101-2B100-2BCr100-2BE99-2B101-CAB100-2A101-B2A100-A2B100-2AN100-2BN100-2EF101-2D102-EL101-FH101-Ab2Au101-2Ab101-AnBsK100-2CfK100-2KCf101-2Bs101-2Ao101-HMAb101-2H101-BH101-2FE2(101-2F)102-FE101-2ED101-2D103-HS103-2D102-2D101-3D101-4D100-SD2SDN2-W95-2HSGAo2JAl-2R3AaAc89-2P2M2K9-ZAa87-AwPM2AjT11-2WO12-Ai72-AwM2Aj15-Bb9-BaAi-3BpAp6-2Dp2CaAi57-Bq2JT16-AlAj6-Ba7-6Ap5-2Ah55-Bf2J19-AlTAl3Ae21-Ah104-Bv104-Ai104-AqCy104-3Ad104-Bk104-Bo104-Fl2(103-Ch)104-Cl103-Bw102-Dg102-Db101-DdEm101-Db102-Fv102-Ah103-V102-CaZ102-Aa2BfT100-X2BfAkOBf98-2JI3X98-2J2I2CeO100-2PIO102-IAk2O102-2O103-O5788-10B2A3C6Y4C8A3C67-F2B100-2CrF100-F2Cr100-E2F98-BD2H100-2B100-ABF101-BE101-EF101-SN101-NFn101-2D101-LH102-2L101-2M102-MJ101-JM102-2J101-KP101-3Ax100-TRAx100-AoTEj101-2Bs101-HGAo100-2NH101-FES100-3F100-4F100-3F101-2EF100-D2E102-DE103-DE102-2D102-DE103-2E104-Fn4XAl104-2AaAl104-2RW104-WO11-Ai92-AzK8-Bm-Bp2Ba9-DpCsCaBc78-Ak6-Af5-2BaAp2Ar4Ap4-Av78-2BfBiBq2Ae20-Av2(Ah104-)Bc104-2Ah104-FtAtFtEy104-Dk104-2(Dy103-)Cu104-Do103-Cj103-Cd101-DnEi101-Cz102-At102-Ca102-Fv103-V102-2V103-Dc2R103-2RAl103-Aj2(103-2Bf)102-2O6103-E3Cr3BA2CYC3Y2CY4C7ACGj2C70-3E100-Cr2F100-2Cr101-2B100-E2B99-2E101-FE101-2E101-2H101-NL101-2N101-AbHCf100-I2K101-XK101-T2Bb101-JBb101-2J102-JP101-2Ao102-2Az101-BbT101-2Ej101-OAjR101-2P101-LP102-2L101-DS102-ED101-2E102-2F101-3F101-3E102-2E102-3E101-E2D102-3D104-AbN2H104-2En104-2OK104-OX11-Ai92-2I8-Cs-EdBa11-2Ca79-Ak6-Af4-El2Aw3ArApDwApBmBp2-BcAv78-O2Bf2AgAe20-AvCy104-Aq104-Ah103-3Ah104-Bk2AtBd2(104-Ch)103-Dy104-2(Do103-)Cd102-Cc102-De102-Du102-At102-Ca103-Bq103-U103-QZW103-2W104-W103-W104-Bi6314-Cr3BA3YC2Y6CAC7ACYGjY73-E2Cr100-2F100-B2F2(100-3B)98-3E100-2E101-D2E100-HN101-AbCi101-2P102-AjP101-KAj101-CfK102-Bb102-2Bb101-2Az102-P102-IP102-Az102-2Ax101-2Ej102-2Bb101-CfBb101-AuBsK101-HAb101-SN102-2D101-D2F101-2(2F102-)EF102-FE103-3E101-3D102-DNH104-HM104-IP104-O2K7-ArDk95-2I5-DxBz97-X8-DzArEd13-Bc79-Dc6-Cp3-Ap2DwAp3Ar2Ct2BmAiBc-AhCy78-2AjTUAsAc20-AqCy104-Ad104-Aq103-AqAd104-EyBkFzBdBo104-Ch104-Do104-Ch103-Er103-Do103-Cl2(102-Bw)102-Bj102-Bv103-Bg2(103-As)Am104-Aa104-Be103-Q104-Bi6421-BC4Y3CAC10A3C3Y76-Cr101-2BF100-2(2B101-)3F98-2D2G98-E2D101-ED100-3L100-AoG101-PAo102-AkAn101-2Cf101-ZFa101-2R102-RU101-2Az101-2I102-2P101-2An102-2(Cf102-Bb)102-2Bb102-K102-IP101-2(2G102-)NAu101-2(FE102-)2E102-2E104-DE102-2D103-2N104-Au104-GAu9-GkAm93-2JAo5-Ar2-Ch95-P3-2Ad2-Bo96-X2-2FpGhDo3-Ar94-2Dc5-2Dz-BhDzArDwAp3Ar2CtEdAwBc2BvAhCy79-2DcZAcZ20-Aq2(104-Ad)104-2At3-Bj100-2BjBo-BoCu104-Do103-Hq104-Er103-Ch103-Do102-Cw102-Bt103-Bt102-Bc102-Dw103-Bg2(104-Ec)104-R103-R104-T6525-CpA6C12A4C3Y77-2P102-P101-3F100-2E102-2E100-3N98-D2G100-2Dv101-2N100-2JL100-P2J101-2An101-CfCm101-FaEj101-HaU102-Gp102-AzFq101-CfEu102-ICo101-2K101-OK102-2O101-2Bb102-2R101-CfEc102-I102-AbJ102-AuAb102-S102-DS102-2D102-ED102-2E104-E103-2D102-3S103-3NH101-2NLG5-EcQ95-GM2R2BpT2-Z97-Aa2Bp4-Bo97-2Ad3-Bj100-DkGhBv2-2CvUAs2Bh2AgDa2Ar2Ed2Aw2AhAv2Aq79-DkDcBvAsZ20-Ad104-Aq104-Ay104-2At3-Fz100-Bn2Bj-DkBl104-Hk103-Hq104-Hw2(103-Hi)102-Dl102-Hj103-Bd102-Ca2(103-Bg)104-Fq104-Aj104-T103-Al6632-3CAC11A6C2Y79-3D100-H2D101-J101-FE102-2E101-2E99-D2H99-3E100-NDv101-2H101-2L101-AoBsL100-CfBs101-2Co101-FaCoEj100-Gk2Eu101-Fv102-EjFv102-Co102-2Co101-CfAx102-Cm102-2Ej102-Ej102-2Ec101-2(2Aa102-)I102-2I102-2J102-DJ102-DAu102-ED103-2(D104-)S2H104-2G103-AuKAmOBf2T104-W104-Bd103-Bd102-Dz-2Aa2BeAmV6-2AwCs4Ah83-2Dz6-VAs3BhAw7-AqCy104-Ah104-Ay104-2BcGg2-FzCn100-BnFz2-Bj104-Hk104-Dl103-Cu103-Er103-Hi102-Hj103-Bo102-Bd102-Ba103-Go104-Fq104-T103-TAl103-W6739-11A4C6Y82-ED101-FE100-3F100-PSF101-S102-2D99-D2H100-E2D99-2ED100-3E100-AuHD101-L101-GL101-K2G101-EjAo101-EjCf100-2Bb102-Bb102-CoAx102-CoBb2(101-2Ax)102-2Co101-2Eu102-2Hr101-Q2(Ec102-)BbT102-XO102-2(J103-)H103-D103-EDv103-2Dv104-GLAu104-AbPAk104-2AkT104-Al104-2(At103-)Af2AaRAkR10-3AhAv90-AmAa2AsAeBq2Aw2Dp4-CaBc104-Ai104-Gy104-2BcGcGe2BcCn104-Hj104-Eb104-Dl2(103-Cu)103-Hj102-Hj103-Cn102-Cn2(103-Bp)104-2Fa103-Fa6949-4A8C7Y84-DA101-F2D100-2B101-B101-GF102-G101-2Dv101-DS100-3D100-2D101-2D100-2HD100-2LH101-LG101-2G101-Ao101-2BbAo100-2AxCm101-2Gd102-Ax102-2Ax101-2Ax102-CoAx101-2Fa102-2Fa101-2Gk101-2ZGk101-EcFq102-AjAl101-IAo102-AbAo102-HAu102-AuD103-2(D104-)2Au104-2GCe104-XK2(Aj104-)Bg104-2Al104-K2Ak104-2AjTAsAcBq2El2DpBc2AvCs2Ca104-Ai104-Da104-BmDzApDzGcBmAq104-Hc104-Ek104-Hw103-Gh103-Bd2(103-Ah)102-Cn2(103-Ad)103-2Fv7159-2B2A6C7Y86-CA102-A101-BA100-3B100-2E101-DE101-G102-DvN101-SDv100-3D100-2SD100-NS101-HL101-2G101-2Ci100-2CiJ101-2Gn101-AnGr101-2An101-3Gd101-2Ax101-Gd2Ax101-AxCf101-2Ax102-BbCm101-2Bb102-Ac102-AaEc102-2(Bf102-X)K102-G103-S103-ED103-DS103-AuL104-MJ104-IAoCe104-AkK104-R104-2K104-XK104-OAk2BeAc-2Ar2Ap2AiBvBp2Ba93-Z10-Ba104-DaBh104-DzAp2HfBgAi104-At104-Dj104-Hq207-At103-Ah103-Bp103-Go102-Ad103-AdEd7265-A2B3CY2(C3Y)88-2(3C100-)2C101-2C100-2BA100-2B100-2S102-2E101-SDv101-2S101-DS100-GNH100-M2J100-2P101-JM101-2J101-GrJ101-HtGr101-Hh2Ax101-CoAx101-2Eu2(102-Co)102-CmEj2(102-Cm)102-BbAx102-EuEj101-EjEu102-AjO102-X2(102-2L)103-D104-Au103-G2(Ab104-J)AoCe104-2I2(104-Ak)O103-2K104-AkEnAjAl7-AiBpBaAwBa92-2Z2UCpDaAw5-Ba104-BqAg104-AfBq2Af2Hf104-Bv104-Hk104-Bl519-Bj103-Bj7372-5C3Y4C91-2C101-3C99-2(3C100-)BA100-3B99-2EF101-2EF100-3E100-DE101-2N101-JG101-J101-2Eu101-KEu101-2K101-2An101-CmHhAn101-EjHh101-AxEj101-EuFa101-2Fa101-3Fq101-2Co101-2Ax101-2Cm102-BbAx102-Bb102-2Ec102-R102-XO102-CiP102-H103-SH103-H104-Ab104-LH104-2J104-2IX104-XAk104-OAj102-KAj104-2AzAjAl6-EdBa3Bm93-Dc2AsU2Cp5-Bm104-2UCv104-AgAs2VAr104-BvAi104-Ai8103-4CY4C93-B2C101-AC100-CA101-2A100-2BA100-BA100-2F102-2B101-2E100-2(2E101-)2H100-CfKBs100-2RCf100-RBb101-CmCf101-K2Az101-AnAz101-AxCm101-2Fq101-2Ha101-HmHa102-Fv102-CoFq101-BbCo101-2O102-2Ax101-2Bb102-EuEj101-IaEj102-Fy103-Fy102-2N2(103-Au)104-Ab104-HL104-Ab104-2J2XK104-KO104-2R102-AjAzR103-BiT2Al4-DaDz3Bm95-2UCpDa5-Cp104-AsAc2Cv104-As2UArGc104-Ba104-Bp8105-7C96-2Y101-2C100-CAC100-C2A100-2BF99-3B99-2E102-2F101-2E100-3E100-2ED100-AbJ101-BsAn101-AjAn100-Eu2Ec100-AxREc101-CmR101-2An101-2Cm101-2Ax101-GkAx101-HbHm101-FvHb102-FvHm101-EuAs101-2O102-Ax102-2Bb102-Co102-BbAx101-IJ102-2J102-2N102-NI102-KAk103-O104-K2(Ab104-)G2I2Ce104-XIX104-Aa3W101-3DcW101-R4WAmCpGp2BgAp104-DaCp104-Ac2CvUAsV104-CtAw104-Ba104-Bc8107-N3AC98-2CB100-2C101-3C100-2A101-FA100-E2F98-3D101-2E101-3E100-2E101-2E100-Ao2H100-BsPBs100-2AzCf100-BbAx101-RCo101-BbCo101-2Cm101-AnCm101-2Cm101-CoBb101-CoHl101-HaFq102-Ec102-AsGp101-EjHr101-AxEj102-2Cf101-BbCf102-Ax102-PAn102-MBs102-G103-X103-I103-TAz104-Ak104-AjT104-2ICe104-X2I2K2O104-R2W102-WBe104-ZAsGpUBhBg4-Ew99-BhV104-VUDgFvAfCpCt104-Gs104-2Ba8214-2A101-2B100-3A101-2A100-2A101-2F101-2E99-S2D100-D2N101-DN100-3E100-ED101-AoN101-PAo101-CfAz100-CoCf101-2BbCo100-3Bb100-2Cf101-AzKCf100-AxAnK100-2AxGr100-CoCmGn100-2Co101-3Co101-Co102-FaBb101-CfFa102-CfAz101-2Ci101-Bs2Ci101-AoM102-P102-LG102-XP102-XAz103-Ak104-AjT103-TI104-PIAb104-2IKX2K2OAj104-Ec103-2Ec8-Do94-ZQUAg4-Cq-Cg97-BgAf3-Fs100-2V3-FvCpGo98-FzFtDp3-2Ed104-Ed8319-B102-AB101-CA100-2AC100-FBA100-2D100-2H101-N2H100-2HFnAb99-3H99-2S2H99-Au2S100-2Ao101-2An100-CoBbAx2(101-2Co)100-3Bb101-2Bb101-KCf101-2An101-2Gn100-Hh2Ci101-BbCi100-BbAxAn101-AxAz101-2P102-P102-JL102-G102-2G101-2G102-G103-J103-X103-OI104-M104-NAb104-Ab2J104-IP2AoI2KT104-2Ec7-Bq95-R6-Eb-Ek95-QAg4-Cj-Cg97-Aw3-Dt-Cg98-AfV2-Gq2-HbGoEd96-2VFtDpDw3-Ed104-Ed8527-B102-2B101-2B100-2JB99-NSD101-3H101-2En100-2HAu100-2HL99-G2L99-AnJ2M99-KAnJ100-Bb2Cm100-2CoBb100-2BbCo100-2Bb101-2Ax101-CfO101-Cm102-AnCm101-CiP101-AuCi101-HpAu101-AzHx101-2AzG100-2L102-LS101-2D102-D102-G102-2G102-Ao103-Ao104-X104-FS104-SG104-AbJG104-Ab2JAbMJOAk104-Z5-AeBq96-R4-Gy2-Ek95-2Am3-Dj3-Cx96-Af2-Dt3-Dh97-2Bq-GiFuGt-2Gs2Ed95-2VCpEdAw4-Ed8839-B102-2B100-2DEB100-2D101-3D100-Au2D100-G2L99-3G100-MGP99-K3P99-Ax2K100-BbAxCf100-EjBbCo99-Bb2Ej100-CmAxEj100-OAzCm99-Cm2OAz100-K2M100-2An101-GCi101-2H101-HxDv102-DDv100-HND101-D102-SD101-2D101-LH102-AuS101-2MS101-GH103-2(2E104-)AuH104-H2SH104-GLJ2PAk104-2Ac3-V2Gs96-QGk-GyBh3-Cn96-ZCpGyBl4-Cz96-CpEdHi3-Do98-EdBd2FuEz-2GsEdDz95-VDaEd2Dp4-Bm9150-EB102-2(2D101-)NS100-2AbH100-AoAbJ100-3P99-KX101-2Ak101-2Bb100-EjRBb100-2EuT100-2Az101-BsP101-2Ao100-PML100-GJG100-2NH100-D2N101-DE101-ED100-3E2(101-2E)101-2D102-DE2(102-D)E103-EF104-BA104-F2B104-HBF104-LAbGCiAkK104-3AjAsHbGsBm97-U6-Ap103-Cz102-Do102-BlCxGoBpHb2Go9463-S102-2N101-HL101-2Ab101-IAn99-2AzKAn99-Cf2AzCf99-2AxCf100-CoBbAx100-R2Bb99-XCfT100-2GP100-M2G100-2CiM100-Au2L100-DNDv100-D3E99-2D2E99-3E100-2EF100-3F100-2F2B99-Cr2F101-3F100-DE102-DB103-2B104-2C104-3B104-FSH104-AuGJIK104-2AjRAcGoBm104-Ap103-V103-GoHa104-BgHb104-Bq9567-J102-MP101-2An101-CmAn101-2Gd100-AxCfAx100-Bb2Ax100-AnAxCf99-IAzAn100-3J100-HGJ100-NHN100-3D100-2DED100-3E100-2EF99-FE3F98-5F98-B2FBF99-4B98-4B100-Cr2B99-3EB100-2BA102-2AC103-3C103-C2B104-2SA104-2MAbCeI104-2XHm2GkAsGpZ101-UQ102-2W102-W2T103-AsAc9879-2(An102-)AxGd101-3Bb100-Ej2Eu100-Cm2Co99-AnCfCmCf99-2IAnI99-2GL100-HGFn100-D2S101-D2S100-2EF100-Cr2F101-Cr2B100-3B100-4B99-3BA98-3B3A97-B5A97-2B4A97-2A4C99-2C2Y102-3Y103-Y2C103-AFE104-HMIJP2AkAl2AsU104-Z102-2Aa102-AlT103-T10087-Hl103-Eu103-Fa102-EcFa101-2Co101-2Cf101-PIH99-2GLG99-2LGL99-2NDv101-DE101-FB101-2F102-B2F100-3BD100-3B100-A4B99-3AB99-2(5A98-)A3C2A97-7C98-3Y2C101-C3A102-2AF104-FnH2Ak2AzEc2Aa10919-Z102-AxCf102-HJ101-2H101-2D100-NS2F99-2EFB99-3E100-F2(2E102-)2D101-E2D102-EF101-BFB101-3A100-4A100-A2CY100-3C100-4C101-2A2C101-HA2H104-IAjTBfAk11231-E102-DE102-FB101-BA100-FBC100-FBF101-F3B100-2DE101-EDE101-3E101-3B101-B2A101-C2A101-3Y100-4Y100-YC2Y101-3C102-A2S2H11647-C102-2C101-BAC102-B2(A101-2E)A101-EB102-2B102-AC102-2C102-2Y102-2(3Y101-)2YA103-A8944-
